Workbook

Sheet SR3
A2: =SOFR3mo_PX[[#This Row],[Column1]] -> Dates | B2: =SOFR3mo_PX[[#This Row],[Column2]] -> 46174 | C2: =SOFR3mo_PX[[#This Row],[Column3]] -> 46171 | D2: =SOFR3mo_PX[[#This Row],[Column4]] -> 46170 | E2: =SOFR3mo_PX[[#This Row],[Column5]] -> 46169 | F2: =SOFR3mo_PX[[#This Row],[Column6]] -> 46168 | G2: =SOFR3mo_PX[[#This Row],[Column7]] -> 46167 | H2: =SOFR3mo_PX[[#This Row],[Column8]] -> 46164 | I2: =SOFR3mo_PX[[#This Row],[Column9]] -> 46163 | J2: =SOFR3mo_PX[[#This Row],[Column10]] -> 46162 | K2: =SOFR3mo_PX[[#This Row],[Column11]] -> 46161 | L2: =SOFR3mo_PX[[#This Row],[Column12]] -> 46160 | M2: =SOFR3mo_PX[[#This Row],[Column13]] -> 46157 | N2: =SOFR3mo_PX[[#This Row],[Column14]] -> 46156 | O2: =SOFR3mo_PX[[#This Row],[Column15]] -> 46155 | P2: =SOFR3mo_PX[[#This Row],[Column16]] -> 46154 | Q2: =SOFR3mo_PX[[#This Row],[Column17]] -> 46153 | R2: =SOFR3mo_PX[[#This Row],[Column18]] -> 46150 | S2: =SOFR3mo_PX[[#This Row],[Column19]] -> 46149 | T2: =SOFR3mo_PX[[#This Row],[Column20]] -> 46148 | U2: =SOFR3mo_PX[[#This Row],[Column21]] -> 46147 | V2: =SOFR3mo_PX[[#This Row],[Column22]] -> 46146 | W2: =SOFR3mo_PX[[#This Row],[Column23]] -> 46143 | X2: =SOFR3mo_PX[[#This Row],[Column24]] -> 46142 | Y2: =SOFR3mo_PX[[#This Row],[Column25]] -> 46141 | Z2: =SOFR3mo_PX[[#This Row],[Column26]] -> 46140 | AA2: =SOFR3mo_PX[[#This Row],[Column27]] -> 46139 | AB2: =SOFR3mo_PX[[#This Row],[Column28]] -> 46136 | AC2: =SOFR3mo_PX[[#This Row],[Column29]] -> 46135 | AD2: =SOFR3mo_PX[[#This Row],[Column30]] -> 46134 | AE2: =SOFR3mo_PX[[#This Row],[Column31]] -> 46133 | AF2: =SOFR3mo_PX[[#This Row],[Column32]] -> 46132 | AG2: =SOFR3mo_PX[[#This Row],[Column33]] -> 46129 | AH2: =SOFR3mo_PX[[#This Row],[Column34]] -> 46128 | AI2: =SOFR3mo_PX[[#This Row],[Column35]] -> 46127 | AJ2: =SOFR3mo_PX[[#This Row],[Column36]] -> 46126 | AK2: =SOFR3mo_PX[[#This Row],[Column37]] -> 46125 | AL2: =SOFR3mo_PX[[#This Row],[Column38]] -> 46122 | AM2: =SOFR3mo_PX[[#This Row],[Column39]] -> 46121 | AN2: =SOFR3mo_PX[[#This Row],[Column40]] -> 46120 | AO2: =SOFR3mo_PX[[#This Row],[Column41]] -> 46119 | AP2: =SOFR3mo_PX[[#This Row],[Column42]] -> 46118 | AQ2: =SOFR3mo_PX[[#This Row],[Column43]] -> 46115 | AR2: =SOFR3mo_PX[[#This Row],[Column44]] -> 46114
A3: ='cont list_0'!I6 -> H26 | B3: =SOFR3mo_PX[[#This Row],[Column2]] -> 1264197 | C3: =SOFR3mo_PX[[#This Row],[Column3]] -> 1264197 | D3: =SOFR3mo_PX[[#This Row],[Column4]] -> 1259500 | E3: =SOFR3mo_PX[[#This Row],[Column5]] -> 1265901 | F3: =SOFR3mo_PX[[#This Row],[Column6]] -> 1261614 | G3: =SOFR3mo_PX[[#This Row],[Column7]] -> 1281279 | H3: =SOFR3mo_PX[[#This Row],[Column8]] -> 1281279 | I3: =SOFR3mo_PX[[#This Row],[Column9]] -> 1282558 | J3: =SOFR3mo_PX[[#This Row],[Column10]] -> 1294002 | K3: =SOFR3mo_PX[[#This Row],[Column11]] -> 1293609 | L3: =SOFR3mo_PX[[#This Row],[Column12]] -> 1285094 | M3: =SOFR3mo_PX[[#This Row],[Column13]] -> 1287215 | N3: =SOFR3mo_PX[[#This Row],[Column14]] -> 1283535 | O3: =SOFR3mo_PX[[#This Row],[Column15]] -> 1291699 | P3: =SOFR3mo_PX[[#This Row],[Column16]] -> 1296220 | Q3: =SOFR3mo_PX[[#This Row],[Column17]] -> 1258708 | R3: =SOFR3mo_PX[[#This Row],[Column18]] -> 1275889 | S3: =SOFR3mo_PX[[#This Row],[Column19]] -> 1275824 | T3: =SOFR3mo_PX[[#This Row],[Column20]] -> 1267709 | U3: =SOFR3mo_PX[[#This Row],[Column21]] -> 1272437 | V3: =SOFR3mo_PX[[#This Row],[Column22]] -> 1266890 | W3: =SOFR3mo_PX[[#This Row],[Column23]] -> 1256190 | X3: =SOFR3mo_PX[[#This Row],[Column24]] -> 1261004 | Y3: =SOFR3mo_PX[[#This Row],[Column25]] -> 1241344 | Z3: =SOFR3mo_PX[[#This Row],[Column26]] -> 1251870 | AA3: =SOFR3mo_PX[[#This Row],[Column27]] -> 1248920 | AB3: =SOFR3mo_PX[[#This Row],[Column28]] -> 1242329 | AC3: =SOFR3mo_PX[[#This Row],[Column29]] -> 1250509 | AD3: =SOFR3mo_PX[[#This Row],[Column30]] -> 1273849 | AE3: =SOFR3mo_PX[[#This Row],[Column31]] -> 1278079 | AF3: =SOFR3mo_PX[[#This Row],[Column32]] -> 1265693 | AG3: =SOFR3mo_PX[[#This Row],[Column33]] -> 1296164 | AH3: =SOFR3mo_PX[[#This Row],[Column34]] -> 1234253 | AI3: =SOFR3mo_PX[[#This Row],[Column35]] -> 1230574 | AJ3: =SOFR3mo_PX[[#This Row],[Column36]] -> 1218653 | AK3: =SOFR3mo_PX[[#This Row],[Column37]] -> 1216403 | AL3: =SOFR3mo_PX[[#This Row],[Column38]] -> 1217492 | AM3: =SOFR3mo_PX[[#This Row],[Column39]] -> 1215896 | AN3: =SOFR3mo_PX[[#This Row],[Column40]] -> 1219583 | AO3: =SOFR3mo_PX[[#This Row],[Column41]] -> 1183264 | AP3: =SOFR3mo_PX[[#This Row],[Column42]] -> 1180422 | AQ3: =SOFR3mo_PX[[#This Row],[Column43]] -> 1173264 | AR3: =SOFR3mo_PX[[#This Row],[Column44]] -> 1178767
A4: ='cont list_0'!I7 -> M26 | B4: =SOFR3mo_PX[[#This Row],[Column2]] -> 1363116 | C4: =SOFR3mo_PX[[#This Row],[Column3]] -> 1363116 | D4: =SOFR3mo_PX[[#This Row],[Column4]] -> 1344797 | E4: =SOFR3mo_PX[[#This Row],[Column5]] -> 1360292 | F4: =SOFR3mo_PX[[#This Row],[Column6]] -> 1340893 | G4: =SOFR3mo_PX[[#This Row],[Column7]] -> 1346607 | H4: =SOFR3mo_PX[[#This Row],[Column8]] -> 1346607 | I4: =SOFR3mo_PX[[#This Row],[Column9]] -> 1320775 | J4: =SOFR3mo_PX[[#This Row],[Column10]] -> 1323873 | K4: =SOFR3mo_PX[[#This Row],[Column11]] -> 1321973 | L4: =SOFR3mo_PX[[#This Row],[Column12]] -> 1323354 | M4: =SOFR3mo_PX[[#This Row],[Column13]] -> 1297332 | N4: =SOFR3mo_PX[[#This Row],[Column14]] -> 1293681 | O4: =SOFR3mo_PX[[#This Row],[Column15]] -> 1282357 | P4: =SOFR3mo_PX[[#This Row],[Column16]] -> 1288683 | Q4: =SOFR3mo_PX[[#This Row],[Column17]] -> 1258962 | R4: =SOFR3mo_PX[[#This Row],[Column18]] -> 1260285 | S4: =SOFR3mo_PX[[#This Row],[Column19]] -> 1282346 | T4: =SOFR3mo_PX[[#This Row],[Column20]] -> 1263827 | U4: =SOFR3mo_PX[[#This Row],[Column21]] -> 1253177 | V4: =SOFR3mo_PX[[#This Row],[Column22]] -> 1225764 | W4: =SOFR3mo_PX[[#This Row],[Column23]] -> 1255447 | X4: =SOFR3mo_PX[[#This Row],[Column24]] -> 1253773 | Y4: =SOFR3mo_PX[[#This Row],[Column25]] -> 1241811 | Z4: =SOFR3mo_PX[[#This Row],[Column26]] -> 1225715 | AA4: =SOFR3mo_PX[[#This Row],[Column27]] -> 1214224 | AB4: =SOFR3mo_PX[[#This Row],[Column28]] -> 1225850 | AC4: =SOFR3mo_PX[[#This Row],[Column29]] -> 1228856 | AD4: =SOFR3mo_PX[[#This Row],[Column30]] -> 1224745 | AE4: =SOFR3mo_PX[[#This Row],[Column31]] -> 1233345 | AF4: =SOFR3mo_PX[[#This Row],[Column32]] -> 1244256 | AG4: =SOFR3mo_PX[[#This Row],[Column33]] -> 1244990 | AH4: =SOFR3mo_PX[[#This Row],[Column34]] -> 1229998 | AI4: =SOFR3mo_PX[[#This Row],[Column35]] -> 1235115 | AJ4: =SOFR3mo_PX[[#This Row],[Column36]] -> 1226152 | AK4: =SOFR3mo_PX[[#This Row],[Column37]] -> 1228580 | AL4: =SOFR3mo_PX[[#This Row],[Column38]] -> 1220727 | AM4: =SOFR3mo_PX[[#This Row],[Column39]] -> 1231199 | AN4: =SOFR3mo_PX[[#This Row],[Column40]] -> 1238002 | AO4: =SOFR3mo_PX[[#This Row],[Column41]] -> 1245240 | AP4: =SOFR3mo_PX[[#This Row],[Column42]] -> 1245777 | AQ4: =SOFR3mo_PX[[#This Row],[Column43]] -> 1242501 | AR4: =SOFR3mo_PX[[#This Row],[Column44]] -> 1231457
A5: ='cont list_0'!I8 -> U26 | B5: =SOFR3mo_PX[[#This Row],[Column2]] -> 1441434 | C5: =SOFR3mo_PX[[#This Row],[Column3]] -> 1441434 | D5: =SOFR3mo_PX[[#This Row],[Column4]] -> 1441302 | E5: =SOFR3mo_PX[[#This Row],[Column5]] -> 1413425 | F5: =SOFR3mo_PX[[#This Row],[Column6]] -> 1402683 | G5: =SOFR3mo_PX[[#This Row],[Column7]] -> 1390354 | H5: =SOFR3mo_PX[[#This Row],[Column8]] -> 1390354 | I5: =SOFR3mo_PX[[#This Row],[Column9]] -> 1361732 | J5: =SOFR3mo_PX[[#This Row],[Column10]] -> 1380295 | K5: =SOFR3mo_PX[[#This Row],[Column11]] -> 1385212 | L5: =SOFR3mo_PX[[#This Row],[Column12]] -> 1364431 | M5: =SOFR3mo_PX[[#This Row],[Column13]] -> 1371895 | N5: =SOFR3mo_PX[[#This Row],[Column14]] -> 1385479 | O5: =SOFR3mo_PX[[#This Row],[Column15]] -> 1382717 | P5: =SOFR3mo_PX[[#This Row],[Column16]] -> 1360639 | Q5: =SOFR3mo_PX[[#This Row],[Column17]] -> 1302360 | R5: =SOFR3mo_PX[[#This Row],[Column18]] -> 1304712 | S5: =SOFR3mo_PX[[#This Row],[Column19]] -> 1287176 | T5: =SOFR3mo_PX[[#This Row],[Column20]] -> 1280994 | U5: =SOFR3mo_PX[[#This Row],[Column21]] -> 1261691 | V5: =SOFR3mo_PX[[#This Row],[Column22]] -> 1248872 | W5: =SOFR3mo_PX[[#This Row],[Column23]] -> 1225308 | X5: =SOFR3mo_PX[[#This Row],[Column24]] -> 1211239 | Y5: =SOFR3mo_PX[[#This Row],[Column25]] -> 1199860 | Z5: =SOFR3mo_PX[[#This Row],[Column26]] -> 1159173 | AA5: =SOFR3mo_PX[[#This Row],[Column27]] -> 1145603 | AB5: =SOFR3mo_PX[[#This Row],[Column28]] -> 1146489 | AC5: =SOFR3mo_PX[[#This Row],[Column29]] -> 1140932 | AD5: =SOFR3mo_PX[[#This Row],[Column30]] -> 1119602 | AE5: =SOFR3mo_PX[[#This Row],[Column31]] -> 1123377 | AF5: =SOFR3mo_PX[[#This Row],[Column32]] -> 1115571 | AG5: =SOFR3mo_PX[[#This Row],[Column33]] -> 1181927 | AH5: =SOFR3mo_PX[[#This Row],[Column34]] -> 1136951 | AI5: =SOFR3mo_PX[[#This Row],[Column35]] -> 1135835 | AJ5: =SOFR3mo_PX[[#This Row],[Column36]] -> 1161935 | AK5: =SOFR3mo_PX[[#This Row],[Column37]] -> 1161515 | AL5: =SOFR3mo_PX[[#This Row],[Column38]] -> 1175691 | AM5: =SOFR3mo_PX[[#This Row],[Column39]] -> 1164171 | AN5: =SOFR3mo_PX[[#This Row],[Column40]] -> 1165477 | AO5: =SOFR3mo_PX[[#This Row],[Column41]] -> 1174098 | AP5: =SOFR3mo_PX[[#This Row],[Column42]] -> 1173757 | AQ5: =SOFR3mo_PX[[#This Row],[Column43]] -> 1173873 | AR5: =SOFR3mo_PX[[#This Row],[Column44]] -> 1166618
A6: ='cont list_0'!I9 -> Z26 | B6: =SOFR3mo_PX[[#This Row],[Column2]] -> 1563980 | C6: =SOFR3mo_PX[[#This Row],[Column3]] -> 1563980 | D6: =SOFR3mo_PX[[#This Row],[Column4]] -> 1565606 | E6: =SOFR3mo_PX[[#This Row],[Column5]] -> 1548820 | F6: =SOFR3mo_PX[[#This Row],[Column6]] -> 1548828 | G6: =SOFR3mo_PX[[#This Row],[Column7]] -> 1553506 | H6: =SOFR3mo_PX[[#This Row],[Column8]] -> 1553506 | I6: =SOFR3mo_PX[[#This Row],[Column9]] -> 1559757 | J6: =SOFR3mo_PX[[#This Row],[Column10]] -> 1561669 | K6: =SOFR3mo_PX[[#This Row],[Column11]] -> 1597349 | L6: =SOFR3mo_PX[[#This Row],[Column12]] -> 1576113 | M6: =SOFR3mo_PX[[#This Row],[Column13]] -> 1574266 | N6: =SOFR3mo_PX[[#This Row],[Column14]] -> 1587796 | O6: =SOFR3mo_PX[[#This Row],[Column15]] -> 1584795 | P6: =SOFR3mo_PX[[#This Row],[Column16]] -> 1611789 | Q6: =SOFR3mo_PX[[#This Row],[Column17]] -> 1591464 | R6: =SOFR3mo_PX[[#This Row],[Column18]] -> 1578041 | S6: =SOFR3mo_PX[[#This Row],[Column19]] -> 1571393 | T6: =SOFR3mo_PX[[#This Row],[Column20]] -> 1582377 | U6: =SOFR3mo_PX[[#This Row],[Column21]] -> 1578555 | V6: =SOFR3mo_PX[[#This Row],[Column22]] -> 1572436 | W6: =SOFR3mo_PX[[#This Row],[Column23]] -> 1569464 | X6: =SOFR3mo_PX[[#This Row],[Column24]] -> 1546657 | Y6: =SOFR3mo_PX[[#This Row],[Column25]] -> 1527515 | Z6: =SOFR3mo_PX[[#This Row],[Column26]] -> 1511888 | AA6: =SOFR3mo_PX[[#This Row],[Column27]] -> 1484698 | AB6: =SOFR3mo_PX[[#This Row],[Column28]] -> 1450593 | AC6: =SOFR3mo_PX[[#This Row],[Column29]] -> 1422829 | AD6: =SOFR3mo_PX[[#This Row],[Column30]] -> 1428616 | AE6: =SOFR3mo_PX[[#This Row],[Column31]] -> 1438156 | AF6: =SOFR3mo_PX[[#This Row],[Column32]] -> 1437603 | AG6: =SOFR3mo_PX[[#This Row],[Column33]] -> 1460474 | AH6: =SOFR3mo_PX[[#This Row],[Column34]] -> 1442030 | AI6: =SOFR3mo_PX[[#This Row],[Column35]] -> 1451099 | AJ6: =SOFR3mo_PX[[#This Row],[Column36]] -> 1439880 | AK6: =SOFR3mo_PX[[#This Row],[Column37]] -> 1449750 | AL6: =SOFR3mo_PX[[#This Row],[Column38]] -> 1449830 | AM6: =SOFR3mo_PX[[#This Row],[Column39]] -> 1444484 | AN6: =SOFR3mo_PX[[#This Row],[Column40]] -> 1436586 | AO6: =SOFR3mo_PX[[#This Row],[Column41]] -> 1482219 | AP6: =SOFR3mo_PX[[#This Row],[Column42]] -> 1470307 | AQ6: =SOFR3mo_PX[[#This Row],[Column43]] -> 1464008 | AR6: =SOFR3mo_PX[[#This Row],[Column44]] -> 1456972
A7: ='cont list_0'!I10 -> H27 | B7: =SOFR3mo_PX[[#This Row],[Column2]] -> 1027566 | C7: =SOFR3mo_PX[[#This Row],[Column3]] -> 1027566 | D7: =SOFR3mo_PX[[#This Row],[Column4]] -> 1053220 | E7: =SOFR3mo_PX[[#This Row],[Column5]] -> 1040753 | F7: =SOFR3mo_PX[[#This Row],[Column6]] -> 1039214 | G7: =SOFR3mo_PX[[#This Row],[Column7]] -> 1039886 | H7: =SOFR3mo_PX[[#This Row],[Column8]] -> 1039886 | I7: =SOFR3mo_PX[[#This Row],[Column9]] -> 1027553 | J7: =SOFR3mo_PX[[#This Row],[Column10]] -> 1019013 | K7: =SOFR3mo_PX[[#This Row],[Column11]] -> 1013491 | L7: =SOFR3mo_PX[[#This Row],[Column12]] -> 1001541 | M7: =SOFR3mo_PX[[#This Row],[Column13]] -> 1002056 | N7: =SOFR3mo_PX[[#This Row],[Column14]] -> 1009422 | O7: =SOFR3mo_PX[[#This Row],[Column15]] -> 1015878 | P7: =SOFR3mo_PX[[#This Row],[Column16]] -> 1030612 | Q7: =SOFR3mo_PX[[#This Row],[Column17]] -> 1006097 | R7: =SOFR3mo_PX[[#This Row],[Column18]] -> 999593 | S7: =SOFR3mo_PX[[#This Row],[Column19]] -> 1014309 | T7: =SOFR3mo_PX[[#This Row],[Column20]] -> 1002729 | U7: =SOFR3mo_PX[[#This Row],[Column21]] -> 998837 | V7: =SOFR3mo_PX[[#This Row],[Column22]] -> 983978 | W7: =SOFR3mo_PX[[#This Row],[Column23]] -> 966142 | X7: =SOFR3mo_PX[[#This Row],[Column24]] -> 955810 | Y7: =SOFR3mo_PX[[#This Row],[Column25]] -> 953797 | Z7: =SOFR3mo_PX[[#This Row],[Column26]] -> 970050 | AA7: =SOFR3mo_PX[[#This Row],[Column27]] -> 961388 | AB7: =SOFR3mo_PX[[#This Row],[Column28]] -> 947054 | AC7: =SOFR3mo_PX[[#This Row],[Column29]] -> 934671 | AD7: =SOFR3mo_PX[[#This Row],[Column30]] -> 949208 | AE7: =SOFR3mo_PX[[#This Row],[Column31]] -> 955389 | AF7: =SOFR3mo_PX[[#This Row],[Column32]] -> 946691 | AG7: =SOFR3mo_PX[[#This Row],[Column33]] -> 944578 | AH7: =SOFR3mo_PX[[#This Row],[Column34]] -> 943040 | AI7: =SOFR3mo_PX[[#This Row],[Column35]] -> 948226 | AJ7: =SOFR3mo_PX[[#This Row],[Column36]] -> 954455 | AK7: =SOFR3mo_PX[[#This Row],[Column37]] -> 947042 | AL7: =SOFR3mo_PX[[#This Row],[Column38]] -> 943023 | AM7: =SOFR3mo_PX[[#This Row],[Column39]] -> 945925 | AN7: =SOFR3mo_PX[[#This Row],[Column40]] -> 946387 | AO7: =SOFR3mo_PX[[#This Row],[Column41]] -> 962742 | AP7: =SOFR3mo_PX[[#This Row],[Column42]] -> 960453 | AQ7: =SOFR3mo_PX[[#This Row],[Column43]] -> 966082 | AR7: =SOFR3mo_PX[[#This Row],[Column44]] -> 959835
A8: ='cont list_0'!I11 -> M27 | B8: =SOFR3mo_PX[[#This Row],[Column2]] -> 1201412 | C8: =SOFR3mo_PX[[#This Row],[Column3]] -> 1201412 | D8: =SOFR3mo_PX[[#This Row],[Column4]] -> 1208144 | E8: =SOFR3mo_PX[[#This Row],[Column5]] -> 1201962 | F8: =SOFR3mo_PX[[#This Row],[Column6]] -> 1208746 | G8: =SOFR3mo_PX[[#This Row],[Column7]] -> 1214289 | H8: =SOFR3mo_PX[[#This Row],[Column8]] -> 1214289 | I8: =SOFR3mo_PX[[#This Row],[Column9]] -> 1175056 | J8: =SOFR3mo_PX[[#This Row],[Column10]] -> 1174811 | K8: =SOFR3mo_PX[[#This Row],[Column11]] -> 1181295 | L8: =SOFR3mo_PX[[#This Row],[Column12]] -> 1171362 | M8: =SOFR3mo_PX[[#This Row],[Column13]] -> 1189876 | N8: =SOFR3mo_PX[[#This Row],[Column14]] -> 1172866 | O8: =SOFR3mo_PX[[#This Row],[Column15]] -> 1178534 | P8: =SOFR3mo_PX[[#This Row],[Column16]] -> 1206764 | Q8: =SOFR3mo_PX[[#This Row],[Column17]] -> 1118896 | R8: =SOFR3mo_PX[[#This Row],[Column18]] -> 1119520 | S8: =SOFR3mo_PX[[#This Row],[Column19]] -> 1119867 | T8: =SOFR3mo_PX[[#This Row],[Column20]] -> 1092106 | U8: =SOFR3mo_PX[[#This Row],[Column21]] -> 1092767 | V8: =SOFR3mo_PX[[#This Row],[Column22]] -> 1099075 | W8: =SOFR3mo_PX[[#This Row],[Column23]] -> 1074460 | X8: =SOFR3mo_PX[[#This Row],[Column24]] -> 1050119 | Y8: =SOFR3mo_PX[[#This Row],[Column25]] -> 1059338 | Z8: =SOFR3mo_PX[[#This Row],[Column26]] -> 1003341 | AA8: =SOFR3mo_PX[[#This Row],[Column27]] -> 985628 | AB8: =SOFR3mo_PX[[#This Row],[Column28]] -> 984495 | AC8: =SOFR3mo_PX[[#This Row],[Column29]] -> 978479 | AD8: =SOFR3mo_PX[[#This Row],[Column30]] -> 951393 | AE8: =SOFR3mo_PX[[#This Row],[Column31]] -> 955445 | AF8: =SOFR3mo_PX[[#This Row],[Column32]] -> 961327 | AG8: =SOFR3mo_PX[[#This Row],[Column33]] -> 961546 | AH8: =SOFR3mo_PX[[#This Row],[Column34]] -> 965751 | AI8: =SOFR3mo_PX[[#This Row],[Column35]] -> 974868 | AJ8: =SOFR3mo_PX[[#This Row],[Column36]] -> 977552 | AK8: =SOFR3mo_PX[[#This Row],[Column37]] -> 974647 | AL8: =SOFR3mo_PX[[#This Row],[Column38]] -> 970884 | AM8: =SOFR3mo_PX[[#This Row],[Column39]] -> 979584 | AN8: =SOFR3mo_PX[[#This Row],[Column40]] -> 975320 | AO8: =SOFR3mo_PX[[#This Row],[Column41]] -> 991255 | AP8: =SOFR3mo_PX[[#This Row],[Column42]] -> 982753 | AQ8: =SOFR3mo_PX[[#This Row],[Column43]] -> 983430 | AR8: =SOFR3mo_PX[[#This Row],[Column44]] -> 970704
A9: ='cont list_0'!I12 -> U27 | B9: =SOFR3mo_PX[[#This Row],[Column2]] -> 833603 | C9: =SOFR3mo_PX[[#This Row],[Column3]] -> 833603 | D9: =SOFR3mo_PX[[#This Row],[Column4]] -> 831361 | E9: =SOFR3mo_PX[[#This Row],[Column5]] -> 823923 | F9: =SOFR3mo_PX[[#This Row],[Column6]] -> 834877 | G9: =SOFR3mo_PX[[#This Row],[Column7]] -> 872764 | H9: =SOFR3mo_PX[[#This Row],[Column8]] -> 872764 | I9: =SOFR3mo_PX[[#This Row],[Column9]] -> 854828 | J9: =SOFR3mo_PX[[#This Row],[Column10]] -> 855880 | K9: =SOFR3mo_PX[[#This Row],[Column11]] -> 862285 | L9: =SOFR3mo_PX[[#This Row],[Column12]] -> 856357 | M9: =SOFR3mo_PX[[#This Row],[Column13]] -> 850889 | N9: =SOFR3mo_PX[[#This Row],[Column14]] -> 860140 | O9: =SOFR3mo_PX[[#This Row],[Column15]] -> 855037 | P9: =SOFR3mo_PX[[#This Row],[Column16]] -> 861242 | Q9: =SOFR3mo_PX[[#This Row],[Column17]] -> 824870 | R9: =SOFR3mo_PX[[#This Row],[Column18]] -> 822743 | S9: =SOFR3mo_PX[[#This Row],[Column19]] -> 828587 | T9: =SOFR3mo_PX[[#This Row],[Column20]] -> 819178 | U9: =SOFR3mo_PX[[#This Row],[Column21]] -> 817242 | V9: =SOFR3mo_PX[[#This Row],[Column22]] -> 814030 | W9: =SOFR3mo_PX[[#This Row],[Column23]] -> 805455 | X9: =SOFR3mo_PX[[#This Row],[Column24]] -> 788366 | Y9: =SOFR3mo_PX[[#This Row],[Column25]] -> 775400 | Z9: =SOFR3mo_PX[[#This Row],[Column26]] -> 757382 | AA9: =SOFR3mo_PX[[#This Row],[Column27]] -> 759123 | AB9: =SOFR3mo_PX[[#This Row],[Column28]] -> 771167 | AC9: =SOFR3mo_PX[[#This Row],[Column29]] -> 773015 | AD9: =SOFR3mo_PX[[#This Row],[Column30]] -> 780701 | AE9: =SOFR3mo_PX[[#This Row],[Column31]] -> 775949 | AF9: =SOFR3mo_PX[[#This Row],[Column32]] -> 785276 | AG9: =SOFR3mo_PX[[#This Row],[Column33]] -> 787636 | AH9: =SOFR3mo_PX[[#This Row],[Column34]] -> 781064 | AI9: =SOFR3mo_PX[[#This Row],[Column35]] -> 780580 | AJ9: =SOFR3mo_PX[[#This Row],[Column36]] -> 792699 | AK9: =SOFR3mo_PX[[#This Row],[Column37]] -> 789553 | AL9: =SOFR3mo_PX[[#This Row],[Column38]] -> 801088 | AM9: =SOFR3mo_PX[[#This Row],[Column39]] -> 806129 | AN9: =SOFR3mo_PX[[#This Row],[Column40]] -> 811009 | AO9: =SOFR3mo_PX[[#This Row],[Column41]] -> 814409 | AP9: =SOFR3mo_PX[[#This Row],[Column42]] -> 799991 | AQ9: =SOFR3mo_PX[[#This Row],[Column43]] -> 797622 | AR9: =SOFR3mo_PX[[#This Row],[Column44]] -> 789263
A10: ='cont list_0'!I13 -> Z27 | B10: =SOFR3mo_PX[[#This Row],[Column2]] -> 1100561 | C10: =SOFR3mo_PX[[#This Row],[Column3]] -> 1100561 | D10: =SOFR3mo_PX[[#This Row],[Column4]] -> 1092931 | E10: =SOFR3mo_PX[[#This Row],[Column5]] -> 1083821 | F10: =SOFR3mo_PX[[#This Row],[Column6]] -> 1092241 | G10: =SOFR3mo_PX[[#This Row],[Column7]] -> 1129736 | H10: =SOFR3mo_PX[[#This Row],[Column8]] -> 1129736 | I10: =SOFR3mo_PX[[#This Row],[Column9]] -> 1120370 | J10: =SOFR3mo_PX[[#This Row],[Column10]] -> 1123703 | K10: =SOFR3mo_PX[[#This Row],[Column11]] -> 1139114 | L10: =SOFR3mo_PX[[#This Row],[Column12]] -> 1145264 | M10: =SOFR3mo_PX[[#This Row],[Column13]] -> 1151655 | N10: =SOFR3mo_PX[[#This Row],[Column14]] -> 1130159 | O10: =SOFR3mo_PX[[#This Row],[Column15]] -> 1143425 | P10: =SOFR3mo_PX[[#This Row],[Column16]] -> 1157523 | Q10: =SOFR3mo_PX[[#This Row],[Column17]] -> 1143637 | R10: =SOFR3mo_PX[[#This Row],[Column18]] -> 1132496 | S10: =SOFR3mo_PX[[#This Row],[Column19]] -> 1141438 | T10: =SOFR3mo_PX[[#This Row],[Column20]] -> 1159851 | U10: =SOFR3mo_PX[[#This Row],[Column21]] -> 1171759 | V10: =SOFR3mo_PX[[#This Row],[Column22]] -> 1167146 | W10: =SOFR3mo_PX[[#This Row],[Column23]] -> 1165688 | X10: =SOFR3mo_PX[[#This Row],[Column24]] -> 1151823 | Y10: =SOFR3mo_PX[[#This Row],[Column25]] -> 1115651 | Z10: =SOFR3mo_PX[[#This Row],[Column26]] -> 1091729 | AA10: =SOFR3mo_PX[[#This Row],[Column27]] -> 1096692 | AB10: =SOFR3mo_PX[[#This Row],[Column28]] -> 1107841 | AC10: =SOFR3mo_PX[[#This Row],[Column29]] -> 1102887 | AD10: =SOFR3mo_PX[[#This Row],[Column30]] -> 1118773 | AE10: =SOFR3mo_PX[[#This Row],[Column31]] -> 1110757 | AF10: =SOFR3mo_PX[[#This Row],[Column32]] -> 1107665 | AG10: =SOFR3mo_PX[[#This Row],[Column33]] -> 1106095 | AH10: =SOFR3mo_PX[[#This Row],[Column34]] -> 1082629 | AI10: =SOFR3mo_PX[[#This Row],[Column35]] -> 1092163 | AJ10: =SOFR3mo_PX[[#This Row],[Column36]] -> 1102861 | AK10: =SOFR3mo_PX[[#This Row],[Column37]] -> 1106856 | AL10: =SOFR3mo_PX[[#This Row],[Column38]] -> 1108384 | AM10: =SOFR3mo_PX[[#This Row],[Column39]] -> 1100877 | AN10: =SOFR3mo_PX[[#This Row],[Column40]] -> 1105661 | AO10: =SOFR3mo_PX[[#This Row],[Column41]] -> 1094766 | AP10: =SOFR3mo_PX[[#This Row],[Column42]] -> 1094724 | AQ10: =SOFR3mo_PX[[#This Row],[Column43]] -> 1085545 | AR10: =SOFR3mo_PX[[#This Row],[Column44]] -> 1079084
A11: ='cont list_0'!I14 -> H28 | B11: =SOFR3mo_PX[[#This Row],[Column2]] -> 687749 | C11: =SOFR3mo_PX[[#This Row],[Column3]] -> 687749 | D11: =SOFR3mo_PX[[#This Row],[Column4]] -> 672282 | E11: =SOFR3mo_PX[[#This Row],[Column5]] -> 676543 | F11: =SOFR3mo_PX[[#This Row],[Column6]] -> 720030 | G11: =SOFR3mo_PX[[#This Row],[Column7]] -> 741320 | H11: =SOFR3mo_PX[[#This Row],[Column8]] -> 741320 | I11: =SOFR3mo_PX[[#This Row],[Column9]] -> 729376 | J11: =SOFR3mo_PX[[#This Row],[Column10]] -> 753468 | K11: =SOFR3mo_PX[[#This Row],[Column11]] -> 765038 | L11: =SOFR3mo_PX[[#This Row],[Column12]] -> 762510 | M11: =SOFR3mo_PX[[#This Row],[Column13]] -> 765701 | N11: =SOFR3mo_PX[[#This Row],[Column14]] -> 773212 | O11: =SOFR3mo_PX[[#This Row],[Column15]] -> 773240 | P11: =SOFR3mo_PX[[#This Row],[Column16]] -> 762104 | Q11: =SOFR3mo_PX[[#This Row],[Column17]] -> 693076 | R11: =SOFR3mo_PX[[#This Row],[Column18]] -> 687306 | S11: =SOFR3mo_PX[[#This Row],[Column19]] -> 675902 | T11: =SOFR3mo_PX[[#This Row],[Column20]] -> 668183 | U11: =SOFR3mo_PX[[#This Row],[Column21]] -> 667719 | V11: =SOFR3mo_PX[[#This Row],[Column22]] -> 657644 | W11: =SOFR3mo_PX[[#This Row],[Column23]] -> 655046 | X11: =SOFR3mo_PX[[#This Row],[Column24]] -> 650569 | Y11: =SOFR3mo_PX[[#This Row],[Column25]] -> 649702 | Z11: =SOFR3mo_PX[[#This Row],[Column26]] -> 641359 | AA11: =SOFR3mo_PX[[#This Row],[Column27]] -> 642207 | AB11: =SOFR3mo_PX[[#This Row],[Column28]] -> 638995 | AC11: =SOFR3mo_PX[[#This Row],[Column29]] -> 651431 | AD11: =SOFR3mo_PX[[#This Row],[Column30]] -> 644175 | AE11: =SOFR3mo_PX[[#This Row],[Column31]] -> 650874 | AF11: =SOFR3mo_PX[[#This Row],[Column32]] -> 650357 | AG11: =SOFR3mo_PX[[#This Row],[Column33]] -> 655201 | AH11: =SOFR3mo_PX[[#This Row],[Column34]] -> 639485 | AI11: =SOFR3mo_PX[[#This Row],[Column35]] -> 638871 | AJ11: =SOFR3mo_PX[[#This Row],[Column36]] -> 645518 | AK11: =SOFR3mo_PX[[#This Row],[Column37]] -> 639385 | AL11: =SOFR3mo_PX[[#This Row],[Column38]] -> 646390 | AM11: =SOFR3mo_PX[[#This Row],[Column39]] -> 639433 | AN11: =SOFR3mo_PX[[#This Row],[Column40]] -> 636140 | AO11: =SOFR3mo_PX[[#This Row],[Column41]] -> 633456 | AP11: =SOFR3mo_PX[[#This Row],[Column42]] -> 617599 | AQ11: =SOFR3mo_PX[[#This Row],[Column43]] -> 612798 | AR11: =SOFR3mo_PX[[#This Row],[Column44]] -> 609918
A12: ='cont list_0'!I15 -> M28 | B12: =SOFR3mo_PX[[#This Row],[Column2]] -> 525784 | C12: =SOFR3mo_PX[[#This Row],[Column3]] -> 525784 | D12: =SOFR3mo_PX[[#This Row],[Column4]] -> 532514 | E12: =SOFR3mo_PX[[#This Row],[Column5]] -> 512921 | F12: =SOFR3mo_PX[[#This Row],[Column6]] -> 525081 | G12: =SOFR3mo_PX[[#This Row],[Column7]] -> 535745 | H12: =SOFR3mo_PX[[#This Row],[Column8]] -> 535745 | I12: =SOFR3mo_PX[[#This Row],[Column9]] -> 531001 | J12: =SOFR3mo_PX[[#This Row],[Column10]] -> 535977 | K12: =SOFR3mo_PX[[#This Row],[Column11]] -> 541826 | L12: =SOFR3mo_PX[[#This Row],[Column12]] -> 531711 | M12: =SOFR3mo_PX[[#This Row],[Column13]] -> 522450 | N12: =SOFR3mo_PX[[#This Row],[Column14]] -> 516970 | O12: =SOFR3mo_PX[[#This Row],[Column15]] -> 518266 | P12: =SOFR3mo_PX[[#This Row],[Column16]] -> 521985 | Q12: =SOFR3mo_PX[[#This Row],[Column17]] -> 507435 | R12: =SOFR3mo_PX[[#This Row],[Column18]] -> 510547 | S12: =SOFR3mo_PX[[#This Row],[Column19]] -> 505354 | T12: =SOFR3mo_PX[[#This Row],[Column20]] -> 482590 | U12: =SOFR3mo_PX[[#This Row],[Column21]] -> 487373 | V12: =SOFR3mo_PX[[#This Row],[Column22]] -> 479751 | W12: =SOFR3mo_PX[[#This Row],[Column23]] -> 479249 | X12: =SOFR3mo_PX[[#This Row],[Column24]] -> 477000 | Y12: =SOFR3mo_PX[[#This Row],[Column25]] -> 477598 | Z12: =SOFR3mo_PX[[#This Row],[Column26]] -> 463424 | AA12: =SOFR3mo_PX[[#This Row],[Column27]] -> 460249 | AB12: =SOFR3mo_PX[[#This Row],[Column28]] -> 455252 | AC12: =SOFR3mo_PX[[#This Row],[Column29]] -> 457746 | AD12: =SOFR3mo_PX[[#This Row],[Column30]] -> 452848 | AE12: =SOFR3mo_PX[[#This Row],[Column31]] -> 450539 | AF12: =SOFR3mo_PX[[#This Row],[Column32]] -> 455422 | AG12: =SOFR3mo_PX[[#This Row],[Column33]] -> 458146 | AH12: =SOFR3mo_PX[[#This Row],[Column34]] -> 454066 | AI12: =SOFR3mo_PX[[#This Row],[Column35]] -> 456154 | AJ12: =SOFR3mo_PX[[#This Row],[Column36]] -> 458659 | AK12: =SOFR3mo_PX[[#This Row],[Column37]] -> 455729 | AL12: =SOFR3mo_PX[[#This Row],[Column38]] -> 462014 | AM12: =SOFR3mo_PX[[#This Row],[Column39]] -> 474860 | AN12: =SOFR3mo_PX[[#This Row],[Column40]] -> 473017 | AO12: =SOFR3mo_PX[[#This Row],[Column41]] -> 458263 | AP12: =SOFR3mo_PX[[#This Row],[Column42]] -> 455410 | AQ12: =SOFR3mo_PX[[#This Row],[Column43]] -> 452348 | AR12: =SOFR3mo_PX[[#This Row],[Column44]] -> 447974
A13: ='cont list_0'!I16 -> U28 | B13: =SOFR3mo_PX[[#This Row],[Column2]] -> 465709 | C13: =SOFR3mo_PX[[#This Row],[Column3]] -> 465709 | D13: =SOFR3mo_PX[[#This Row],[Column4]] -> 465470 | E13: =SOFR3mo_PX[[#This Row],[Column5]] -> 468110 | F13: =SOFR3mo_PX[[#This Row],[Column6]] -> 473171 | G13: =SOFR3mo_PX[[#This Row],[Column7]] -> 474223 | H13: =SOFR3mo_PX[[#This Row],[Column8]] -> 474223 | I13: =SOFR3mo_PX[[#This Row],[Column9]] -> 467204 | J13: =SOFR3mo_PX[[#This Row],[Column10]] -> 472857 | K13: =SOFR3mo_PX[[#This Row],[Column11]] -> 469873 | L13: =SOFR3mo_PX[[#This Row],[Column12]] -> 467201 | M13: =SOFR3mo_PX[[#This Row],[Column13]] -> 462369 | N13: =SOFR3mo_PX[[#This Row],[Column14]] -> 460348 | O13: =SOFR3mo_PX[[#This Row],[Column15]] -> 455073 | P13: =SOFR3mo_PX[[#This Row],[Column16]] -> 454996 | Q13: =SOFR3mo_PX[[#This Row],[Column17]] -> 419738 | R13: =SOFR3mo_PX[[#This Row],[Column18]] -> 414255 | S13: =SOFR3mo_PX[[#This Row],[Column19]] -> 418328 | T13: =SOFR3mo_PX[[#This Row],[Column20]] -> 405939 | U13: =SOFR3mo_PX[[#This Row],[Column21]] -> 409716 | V13: =SOFR3mo_PX[[#This Row],[Column22]] -> 403228 | W13: =SOFR3mo_PX[[#This Row],[Column23]] -> 397669 | X13: =SOFR3mo_PX[[#This Row],[Column24]] -> 394070 | Y13: =SOFR3mo_PX[[#This Row],[Column25]] -> 394344 | Z13: =SOFR3mo_PX[[#This Row],[Column26]] -> 389640 | AA13: =SOFR3mo_PX[[#This Row],[Column27]] -> 389999 | AB13: =SOFR3mo_PX[[#This Row],[Column28]] -> 383098 | AC13: =SOFR3mo_PX[[#This Row],[Column29]] -> 389191 | AD13: =SOFR3mo_PX[[#This Row],[Column30]] -> 380815 | AE13: =SOFR3mo_PX[[#This Row],[Column31]] -> 380583 | AF13: =SOFR3mo_PX[[#This Row],[Column32]] -> 376467 | AG13: =SOFR3mo_PX[[#This Row],[Column33]] -> 378396 | AH13: =SOFR3mo_PX[[#This Row],[Column34]] -> 375583 | AI13: =SOFR3mo_PX[[#This Row],[Column35]] -> 374859 | AJ13: =SOFR3mo_PX[[#This Row],[Column36]] -> 376345 | AK13: =SOFR3mo_PX[[#This Row],[Column37]] -> 374455 | AL13: =SOFR3mo_PX[[#This Row],[Column38]] -> 375571 | AM13: =SOFR3mo_PX[[#This Row],[Column39]] -> 373031 | AN13: =SOFR3mo_PX[[#This Row],[Column40]] -> 376019 | AO13: =SOFR3mo_PX[[#This Row],[Column41]] -> 372318 | AP13: =SOFR3mo_PX[[#This Row],[Column42]] -> 367194 | AQ13: =SOFR3mo_PX[[#This Row],[Column43]] -> 364820 | AR13: =SOFR3mo_PX[[#This Row],[Column44]] -> 366028
A14: ='cont list_0'!I17 -> Z28 | B14: =SOFR3mo_PX[[#This Row],[Column2]] -> 400332 | C14: =SOFR3mo_PX[[#This Row],[Column3]] -> 400332 | D14: =SOFR3mo_PX[[#This Row],[Column4]] -> 397240 | E14: =SOFR3mo_PX[[#This Row],[Column5]] -> 396504 | F14: =SOFR3mo_PX[[#This Row],[Column6]] -> 392101 | G14: =SOFR3mo_PX[[#This Row],[Column7]] -> 382735 | H14: =SOFR3mo_PX[[#This Row],[Column8]] -> 382735 | I14: =SOFR3mo_PX[[#This Row],[Column9]] -> 378131 | J14: =SOFR3mo_PX[[#This Row],[Column10]] -> 381858 | K14: =SOFR3mo_PX[[#This Row],[Column11]] -> 367293 | L14: =SOFR3mo_PX[[#This Row],[Column12]] -> 367189 | M14: =SOFR3mo_PX[[#This Row],[Column13]] -> 374861 | N14: =SOFR3mo_PX[[#This Row],[Column14]] -> 376812 | O14: =SOFR3mo_PX[[#This Row],[Column15]] -> 372269 | P14: =SOFR3mo_PX[[#This Row],[Column16]] -> 367082 | Q14: =SOFR3mo_PX[[#This Row],[Column17]] -> 366990 | R14: =SOFR3mo_PX[[#This Row],[Column18]] -> 367058 | S14: =SOFR3mo_PX[[#This Row],[Column19]] -> 373253 | T14: =SOFR3mo_PX[[#This Row],[Column20]] -> 368330 | U14: =SOFR3mo_PX[[#This Row],[Column21]] -> 359319 | V14: =SOFR3mo_PX[[#This Row],[Column22]] -> 355265 | W14: =SOFR3mo_PX[[#This Row],[Column23]] -> 357124 | X14: =SOFR3mo_PX[[#This Row],[Column24]] -> 356227 | Y14: =SOFR3mo_PX[[#This Row],[Column25]] -> 356810 | Z14: =SOFR3mo_PX[[#This Row],[Column26]] -> 348038 | AA14: =SOFR3mo_PX[[#This Row],[Column27]] -> 347928 | AB14: =SOFR3mo_PX[[#This Row],[Column28]] -> 348531 | AC14: =SOFR3mo_PX[[#This Row],[Column29]] -> 348815 | AD14: =SOFR3mo_PX[[#This Row],[Column30]] -> 352032 | AE14: =SOFR3mo_PX[[#This Row],[Column31]] -> 350761 | AF14: =SOFR3mo_PX[[#This Row],[Column32]] -> 352400 | AG14: =SOFR3mo_PX[[#This Row],[Column33]] -> 350335 | AH14: =SOFR3mo_PX[[#This Row],[Column34]] -> 354209 | AI14: =SOFR3mo_PX[[#This Row],[Column35]] -> 356377 | AJ14: =SOFR3mo_PX[[#This Row],[Column36]] -> 360997 | AK14: =SOFR3mo_PX[[#This Row],[Column37]] -> 363691 | AL14: =SOFR3mo_PX[[#This Row],[Column38]] -> 363448 | AM14: =SOFR3mo_PX[[#This Row],[Column39]] -> 366762 | AN14: =SOFR3mo_PX[[#This Row],[Column40]] -> 367043 | AO14: =SOFR3mo_PX[[#This Row],[Column41]] -> 353377 | AP14: =SOFR3mo_PX[[#This Row],[Column42]] -> 352340 | AQ14: =SOFR3mo_PX[[#This Row],[Column43]] -> 353827 | AR14: =SOFR3mo_PX[[#This Row],[Column44]] -> 354612
... A34: ='cont list_0'!I37 -> Z33 | B34: =SOFR3mo_PX[[#This Row],[Column2]] -> 3 | C34: =SOFR3mo_PX[[#This Row],[Column3]] -> 3 | D34: =SOFR3mo_PX[[#This Row],[Column4]] -> 3 | E34: =SOFR3mo_PX[[#This Row],[Column5]] -> 3 | F34: =SOFR3mo_PX[[#This Row],[Column6]] -> 3 | G34: =SOFR3mo_PX[[#This Row],[Column7]] -> 3 | H34: =SOFR3mo_PX[[#This Row],[Column8]] -> 3 | I34: =SOFR3mo_PX[[#This Row],[Column9]] -> 3 | J34: =SOFR3mo_PX[[#This Row],[Column10]] -> 3 | K34: =SOFR3mo_PX[[#This Row],[Column11]] -> 3 | L34: =SOFR3mo_PX[[#This Row],[Column12]] -> 3 | M34: =SOFR3mo_PX[[#This Row],[Column13]] -> 3 | N34: =SOFR3mo_PX[[#This Row],[Column14]] -> 3 | O34: =SOFR3mo_PX[[#This Row],[Column15]] -> 3 | P34: =SOFR3mo_PX[[#This Row],[Column16]] -> 3 | Q34: =SOFR3mo_PX[[#This Row],[Column17]] -> 3 | R34: =SOFR3mo_PX[[#This Row],[Column18]] -> 3 | S34: =SOFR3mo_PX[[#This Row],[Column19]] -> 3 | T34: =SOFR3mo_PX[[#This Row],[Column20]] -> 3 | U34: =SOFR3mo_PX[[#This Row],[Column21]] -> 3 | V34: =SOFR3mo_PX[[#This Row],[Column22]] -> 3 | W34: =SOFR3mo_PX[[#This Row],[Column23]] -> 3 | X34: =SOFR3mo_PX[[#This Row],[Column24]] -> 3 | Y34: =SOFR3mo_PX[[#This Row],[Column25]] -> 3 | Z34: =SOFR3mo_PX[[#This Row],[Column26]] -> 3 | AA34: =SOFR3mo_PX[[#This Row],[Column27]] -> 3 | AB34: =SOFR3mo_PX[[#This Row],[Column28]] -> 3 | AC34: =SOFR3mo_PX[[#This Row],[Column29]] -> 3 | AD34: =SOFR3mo_PX[[#This Row],[Column30]] -> 3 | AE34: =SOFR3mo_PX[[#This Row],[Column31]] -> 3 | AF34: =SOFR3mo_PX[[#This Row],[Column32]] -> 3 | AG34: =SOFR3mo_PX[[#This Row],[Column33]] -> 3 | AH34: =SOFR3mo_PX[[#This Row],[Column34]] -> 3 | AI34: =SOFR3mo_PX[[#This Row],[Column35]] -> 3 | AJ34: =SOFR3mo_PX[[#This Row],[Column36]] -> 3 | AK34: =SOFR3mo_PX[[#This Row],[Column37]] -> 3 | AL34: =SOFR3mo_PX[[#This Row],[Column38]] -> 3 | AM34: =SOFR3mo_PX[[#This Row],[Column39]] -> 3 | AN34: =SOFR3mo_PX[[#This Row],[Column40]] -> 3 | AO34: =SOFR3mo_PX[[#This Row],[Column41]] -> 3 | AP34: =SOFR3mo_PX[[#This Row],[Column42]] -> 3 | AQ34: =SOFR3mo_PX[[#This Row],[Column43]] -> 3 | AR34: =SOFR3mo_PX[[#This Row],[Column44]] -> 3

Sheet FF
A2: =FF_PX[[#This Row],[Column1]] -> Dates | B2: =FF_PX[[#This Row],[Column2]] -> 46174 | C2: =FF_PX[[#This Row],[Column3]] -> 46171 | D2: =FF_PX[[#This Row],[Column4]] -> 46170 | E2: =FF_PX[[#This Row],[Column5]] -> 46169 | F2: =FF_PX[[#This Row],[Column6]] -> 46168 | G2: =FF_PX[[#This Row],[Column7]] -> 46167 | H2: =FF_PX[[#This Row],[Column8]] -> 46164 | I2: =FF_PX[[#This Row],[Column9]] -> 46163 | J2: =FF_PX[[#This Row],[Column10]] -> 46162 | K2: =FF_PX[[#This Row],[Column11]] -> 46161 | L2: =FF_PX[[#This Row],[Column12]] -> 46160 | M2: =FF_PX[[#This Row],[Column13]] -> 46157 | N2: =FF_PX[[#This Row],[Column14]] -> 46156 | O2: =FF_PX[[#This Row],[Column15]] -> 46155 | P2: =FF_PX[[#This Row],[Column16]] -> 46154 | Q2: =FF_PX[[#This Row],[Column17]] -> 46153 | R2: =FF_PX[[#This Row],[Column18]] -> 46150 | S2: =FF_PX[[#This Row],[Column19]] -> 46149 | T2: =FF_PX[[#This Row],[Column20]] -> 46148 | U2: =FF_PX[[#This Row],[Column21]] -> 46147 | V2: =FF_PX[[#This Row],[Column22]] -> 46146 | W2: =FF_PX[[#This Row],[Column23]] -> 46143 | X2: =FF_PX[[#This Row],[Column24]] -> 46142 | Y2: =FF_PX[[#This Row],[Column25]] -> 46141 | Z2: =FF_PX[[#This Row],[Column26]] -> 46140 | AA2: =FF_PX[[#This Row],[Column27]] -> 46139 | AB2: =FF_PX[[#This Row],[Column28]] -> 46136 | AC2: =FF_PX[[#This Row],[Column29]] -> 46135 | AD2: =FF_PX[[#This Row],[Column30]] -> 46134 | AE2: =FF_PX[[#This Row],[Column31]] -> 46133 | AF2: =FF_PX[[#This Row],[Column32]] -> 46132 | AG2: =FF_PX[[#This Row],[Column33]] -> 46129 | AH2: =FF_PX[[#This Row],[Column34]] -> 46128 | AI2: =FF_PX[[#This Row],[Column35]] -> 46127 | AJ2: =FF_PX[[#This Row],[Column36]] -> 46126 | AK2: =FF_PX[[#This Row],[Column37]] -> 46125 | AL2: =FF_PX[[#This Row],[Column38]] -> 46122 | AM2: =FF_PX[[#This Row],[Column39]] -> 46121 | AN2: =FF_PX[[#This Row],[Column40]] -> 46120 | AO2: =FF_PX[[#This Row],[Column41]] -> 46119 | AP2: =FF_PX[[#This Row],[Column42]] -> 46118 | AQ2: =FF_PX[[#This Row],[Column43]] -> 46115 | AR2: =FF_PX[[#This Row],[Column44]] -> 46114 | AS2: =FF_PX[[#This Row],[Column45]] -> 46113 | AT2: =FF_PX[[#This Row],[Column46]] -> 46112 | AU2: =FF_PX[[#This Row],[Column47]] -> 46111 | AV2: =FF_PX[[#This Row],[Column48]] -> 46108 | AW2: =FF_PX[[#This Row],[Column49]] -> 46107 | AX2: =FF_PX[[#This Row],[Column50]] -> 46106 | AY2: =FF_PX[[#This Row],[Column51]] -> 46105 | AZ2: =FF_PX[[#This Row],[Column52]] -> 46104 | BA2: =FF_PX[[#This Row],[Column53]] -> 46101 | BB2: =FF_PX[[#This Row],[Column54]] -> 46100 | BC2: =FF_PX[[#This Row],[Column55]] -> 46099 | BD2: =FF_PX[[#This Row],[Column56]] -> 46098 | BE2: =FF_PX[[#This Row],[Column57]] -> 46097 | BF2: =FF_PX[[#This Row],[Column58]] -> 46094 | BG2: =FF_PX[[#This Row],[Column59]] -> 46093 | BH2: =FF_PX[[#This Row],[Column60]] -> 46092 | BI2: =FF_PX[[#This Row],[Column61]] -> 46091 | BJ2: =FF_PX[[#This Row],[Column62]] -> 46090 | BK2: =FF_PX[[#This Row],[Column63]] -> 46087 | BL2: =FF_PX[[#This Row],[Column64]] -> 46086 | BM2: =FF_PX[[#This Row],[Column65]] -> 46085 | BN2: =FF_PX[[#This Row],[Column66]] -> 46084 | BO2: =FF_PX[[#This Row],[Column67]] -> 46083 | BP2: =FF_PX[[#This Row],[Column68]] -> 46080 | BQ2: =FF_PX[[#This Row],[Column69]] -> 46079 | BR2: =FF_PX[[#This Row],[Column70]] -> 46078 | BS2: =FF_PX[[#This Row],[Column71]] -> 46077 | BT2: =FF_PX[[#This Row],[Column72]] -> 46076 | BU2: =FF_PX[[#This Row],[Column73]] -> 46073 | BV2: =FF_PX[[#This Row],[Column74]] -> 46072 | BW2: =FF_PX[[#This Row],[Column75]] -> 46071 | BX2: =FF_PX[[#This Row],[Column76]] -> 46070 | BY2: =FF_PX[[#This Row],[Column77]] -> 46069 | BZ2: =FF_PX[[#This Row],[Column78]] -> 46066 | CA2: =FF_PX[[#This Row],[Column79]] -> 46065 | CB2: =FF_PX[[#This Row],[Column80]] -> 46064 | CC2: =FF_PX[[#This Row],[Column81]] -> 46063 | CD2: =FF_PX[[#This Row],[Column82]] -> 46062 | CE2: =FF_PX[[#This Row],[Column83]] -> 46059 | CF2: =FF_PX[[#This Row],[Column84]] -> 46058 | CG2: =FF_PX[[#This Row],[Column85]] -> 46057 | CH2: =FF_PX[[#This Row],[Column86]] -> 46056 | CI2: =FF_PX[[#This Row],[Column87]] -> 46055 | CJ2: =FF_PX[[#This Row],[Column88]] -> 46052 | CK2: =FF_PX[[#This Row],[Column89]] -> 46051 | CL2: =FF_PX[[#This Row],[Column90]] -> 46050 | CM2: =FF_PX[[#This Row],[Column91]] -> 46049 | CN2: =FF_PX[[#This Row],[Column92]] -> 46048 | CO2: =FF_PX[[#This Row],[Column93]] -> 46045 | CP2: =FF_PX[[#This Row],[Column94]] -> 46044 | CQ2: =FF_PX[[#This Row],[Column95]] -> 46043 | CR2: =FF_PX[[#This Row],[Column96]] -> 46042 | CS2: =FF_PX[[#This Row],[Column97]] -> 46041 | CT2: =FF_PX[[#This Row],[Column98]] -> 46038 | CU2: =FF_PX[[#This Row],[Column99]] -> 46037 | CV2: =FF_PX[[#This Row],[Column100]] -> 46036 | CW2: =FF_PX[[#This Row],[Column101]] -> 46035 | CX2: =FF_PX[[#This Row],[Column102]] -> 46034 | CY2: =FF_PX[[#This Row],[Column103]] -> 46031 | CZ2: =FF_PX[[#This Row],[Column104]] -> 46030 | DA2: =FF_PX[[#This Row],[Column105]] -> 46029
A3: ='cont list_0'!M6 -> M26 | B3: =FF_PX[[#This Row],[Column2]] -> 323336 | C3: =FF_PX[[#This Row],[Column3]] -> 323336 | D3: =FF_PX[[#This Row],[Column4]] -> 324391 | E3: =FF_PX[[#This Row],[Column5]] -> 324416 | F3: =FF_PX[[#This Row],[Column6]] -> 320965 | G3: =FF_PX[[#This Row],[Column7]] -> 325473 | H3: =FF_PX[[#This Row],[Column8]] -> 325473 | I3: =FF_PX[[#This Row],[Column9]] -> 314232 | J3: =FF_PX[[#This Row],[Column10]] -> 321563 | K3: =FF_PX[[#This Row],[Column11]] -> 339047 | L3: =FF_PX[[#This Row],[Column12]] -> 331499 | M3: =FF_PX[[#This Row],[Column13]] -> 325600 | N3: =FF_PX[[#This Row],[Column14]] -> 347204 | O3: =FF_PX[[#This Row],[Column15]] -> 372190 | P3: =FF_PX[[#This Row],[Column16]] -> 354771 | Q3: =FF_PX[[#This Row],[Column17]] -> 349687 | R3: =FF_PX[[#This Row],[Column18]] -> 345614 | S3: =FF_PX[[#This Row],[Column19]] -> 360148 | T3: =FF_PX[[#This Row],[Column20]] -> 355498 | U3: =FF_PX[[#This Row],[Column21]] -> 358206 | V3: =FF_PX[[#This Row],[Column22]] -> 357134 | W3: =FF_PX[[#This Row],[Column23]] -> 377707 | X3: =FF_PX[[#This Row],[Column24]] -> 422543 | Y3: =FF_PX[[#This Row],[Column25]] -> 423054 | Z3: =FF_PX[[#This Row],[Column26]] -> 422968 | AA3: =FF_PX[[#This Row],[Column27]] -> 425475 | AB3: =FF_PX[[#This Row],[Column28]] -> 425463 | AC3: =FF_PX[[#This Row],[Column29]] -> 416168 | AD3: =FF_PX[[#This Row],[Column30]] -> 410461 | AE3: =FF_PX[[#This Row],[Column31]] -> 419261 | AF3: =FF_PX[[#This Row],[Column32]] -> 423594 | AG3: =FF_PX[[#This Row],[Column33]] -> 424477 | AH3: =FF_PX[[#This Row],[Column34]] -> 417377 | AI3: =FF_PX[[#This Row],[Column35]] -> 416400 | AJ3: =FF_PX[[#This Row],[Column36]] -> 418680 | AK3: =FF_PX[[#This Row],[Column37]] -> 417814 | AL3: =FF_PX[[#This Row],[Column38]] -> 421196 | AM3: =FF_PX[[#This Row],[Column39]] -> 432056 | AN3: =FF_PX[[#This Row],[Column40]] -> 432542 | AO3: =FF_PX[[#This Row],[Column41]] -> 443085 | AP3: =FF_PX[[#This Row],[Column42]] -> 438136 | AQ3: =FF_PX[[#This Row],[Column43]] -> 438181 | AR3: =FF_PX[[#This Row],[Column44]] -> 439019 | AS3: =FF_PX[[#This Row],[Column45]] -> 437364 | AT3: =FF_PX[[#This Row],[Column46]] -> 334518 | AU3: =FF_PX[[#This Row],[Column47]] -> 332764 | AV3: =FF_PX[[#This Row],[Column48]] -> 340817 | AW3: =FF_PX[[#This Row],[Column49]] -> 333754 | AX3: =FF_PX[[#This Row],[Column50]] -> 330360 | AY3: =FF_PX[[#This Row],[Column51]] -> 325809 | AZ3: =FF_PX[[#This Row],[Column52]] -> 326176 | BA3: =FF_PX[[#This Row],[Column53]] -> 322743 | BB3: =FF_PX[[#This Row],[Column54]] -> 330114 | BC3: =FF_PX[[#This Row],[Column55]] -> 333567 | BD3: =FF_PX[[#This Row],[Column56]] -> 345029 | BE3: =FF_PX[[#This Row],[Column57]] -> 308665 | BF3: =FF_PX[[#This Row],[Column58]] -> 316759 | BG3: =FF_PX[[#This Row],[Column59]] -> 305994 | BH3: =FF_PX[[#This Row],[Column60]] -> 299099 | BI3: =FF_PX[[#This Row],[Column61]] -> 305287 | BJ3: =FF_PX[[#This Row],[Column62]] -> 302007 | BK3: =FF_PX[[#This Row],[Column63]] -> 288405 | BL3: =FF_PX[[#This Row],[Column64]] -> 250202 | BM3: =FF_PX[[#This Row],[Column65]] -> 235029 | BN3: =FF_PX[[#This Row],[Column66]] -> 226477 | BO3: =FF_PX[[#This Row],[Column67]] -> 237738 | BP3: =FF_PX[[#This Row],[Column68]] -> 550744 | BQ3: =FF_PX[[#This Row],[Column69]] -> 553778 | BR3: =FF_PX[[#This Row],[Column70]] -> 557938 | BS3: =FF_PX[[#This Row],[Column71]] -> 558466 | BT3: =FF_PX[[#This Row],[Column72]] -> 555397 | BU3: =FF_PX[[#This Row],[Column73]] -> 549043 | BV3: =FF_PX[[#This Row],[Column74]] -> 541193 | BW3: =FF_PX[[#This Row],[Column75]] -> 541578 | BX3: =FF_PX[[#This Row],[Column76]] -> 553960 | BY3: =FF_PX[[#This Row],[Column77]] -> 523356 | BZ3: =FF_PX[[#This Row],[Column78]] -> 523356 | CA3: =FF_PX[[#This Row],[Column79]] -> 525777 | CB3: =FF_PX[[#This Row],[Column80]] -> 525020 | CC3: =FF_PX[[#This Row],[Column81]] -> 525135 | CD3: =FF_PX[[#This Row],[Column82]] -> 535114 | CE3: =FF_PX[[#This Row],[Column83]] -> 538150 | CF3: =FF_PX[[#This Row],[Column84]] -> 509965 | CG3: =FF_PX[[#This Row],[Column85]] -> 512442 | CH3: =FF_PX[[#This Row],[Column86]] -> 517549 | CI3: =FF_PX[[#This Row],[Column87]] -> 531872 | CJ3: =FF_PX[[#This Row],[Column88]] -> 591841 | CK3: =FF_PX[[#This Row],[Column89]] -> 592473 | CL3: =FF_PX[[#This Row],[Column90]] -> 596030 | CM3: =FF_PX[[#This Row],[Column91]] -> 596247 | CN3: =FF_PX[[#This Row],[Column92]] -> 594636 | CO3: =FF_PX[[#This Row],[Column93]] -> 590461 | CP3: =FF_PX[[#This Row],[Column94]] -> 567513 | CQ3: =FF_PX[[#This Row],[Column95]] -> 566668 | CR3: =FF_PX[[#This Row],[Column96]] -> 528958 | CS3: =FF_PX[[#This Row],[Column97]] -> 524403 | CT3: =FF_PX[[#This Row],[Column98]] -> 524403 | CU3: =FF_PX[[#This Row],[Column99]] -> 535449 | CV3: =FF_PX[[#This Row],[Column100]] -> 537924 | CW3: =FF_PX[[#This Row],[Column101]] -> 592384 | CX3: =FF_PX[[#This Row],[Column102]] -> 608289 | CY3: =FF_PX[[#This Row],[Column103]] -> 615684 | CZ3: =FF_PX[[#This Row],[Column104]] -> 623117 | DA3: =FF_PX[[#This Row],[Column105]] -> 634193
A4: ='cont list_0'!M7 -> N26 | B4: =FF_PX[[#This Row],[Column2]] -> 249169 | C4: =FF_PX[[#This Row],[Column3]] -> 249169 | D4: =FF_PX[[#This Row],[Column4]] -> 243531 | E4: =FF_PX[[#This Row],[Column5]] -> 243171 | F4: =FF_PX[[#This Row],[Column6]] -> 242292 | G4: =FF_PX[[#This Row],[Column7]] -> 250240 | H4: =FF_PX[[#This Row],[Column8]] -> 250240 | I4: =FF_PX[[#This Row],[Column9]] -> 235593 | J4: =FF_PX[[#This Row],[Column10]] -> 231524 | K4: =FF_PX[[#This Row],[Column11]] -> 232215 | L4: =FF_PX[[#This Row],[Column12]] -> 251709 | M4: =FF_PX[[#This Row],[Column13]] -> 243400 | N4: =FF_PX[[#This Row],[Column14]] -> 230647 | O4: =FF_PX[[#This Row],[Column15]] -> 245847 | P4: =FF_PX[[#This Row],[Column16]] -> 245191 | Q4: =FF_PX[[#This Row],[Column17]] -> 252083 | R4: =FF_PX[[#This Row],[Column18]] -> 241645 | S4: =FF_PX[[#This Row],[Column19]] -> 238143 | T4: =FF_PX[[#This Row],[Column20]] -> 229140 | U4: =FF_PX[[#This Row],[Column21]] -> 224043 | V4: =FF_PX[[#This Row],[Column22]] -> 220602 | W4: =FF_PX[[#This Row],[Column23]] -> 218558 | X4: =FF_PX[[#This Row],[Column24]] -> 364863 | Y4: =FF_PX[[#This Row],[Column25]] -> 358936 | Z4: =FF_PX[[#This Row],[Column26]] -> 409462 | AA4: =FF_PX[[#This Row],[Column27]] -> 406302 | AB4: =FF_PX[[#This Row],[Column28]] -> 415552 | AC4: =FF_PX[[#This Row],[Column29]] -> 414530 | AD4: =FF_PX[[#This Row],[Column30]] -> 412422 | AE4: =FF_PX[[#This Row],[Column31]] -> 414697 | AF4: =FF_PX[[#This Row],[Column32]] -> 431884 | AG4: =FF_PX[[#This Row],[Column33]] -> 438216 | AH4: =FF_PX[[#This Row],[Column34]] -> 432322 | AI4: =FF_PX[[#This Row],[Column35]] -> 436897 | AJ4: =FF_PX[[#This Row],[Column36]] -> 442797 | AK4: =FF_PX[[#This Row],[Column37]] -> 438533 | AL4: =FF_PX[[#This Row],[Column38]] -> 447470 | AM4: =FF_PX[[#This Row],[Column39]] -> 448145 | AN4: =FF_PX[[#This Row],[Column40]] -> 451884 | AO4: =FF_PX[[#This Row],[Column41]] -> 453119 | AP4: =FF_PX[[#This Row],[Column42]] -> 449934 | AQ4: =FF_PX[[#This Row],[Column43]] -> 449466 | AR4: =FF_PX[[#This Row],[Column44]] -> 444569 | AS4: =FF_PX[[#This Row],[Column45]] -> 462530 | AT4: =FF_PX[[#This Row],[Column46]] -> 436271 | AU4: =FF_PX[[#This Row],[Column47]] -> 442015 | AV4: =FF_PX[[#This Row],[Column48]] -> 451210 | AW4: =FF_PX[[#This Row],[Column49]] -> 477604 | AX4: =FF_PX[[#This Row],[Column50]] -> 477480 | AY4: =FF_PX[[#This Row],[Column51]] -> 476530 | AZ4: =FF_PX[[#This Row],[Column52]] -> 483621 | BA4: =FF_PX[[#This Row],[Column53]] -> 471704 | BB4: =FF_PX[[#This Row],[Column54]] -> 466301 | BC4: =FF_PX[[#This Row],[Column55]] -> 481494 | BD4: =FF_PX[[#This Row],[Column56]] -> 478215 | BE4: =FF_PX[[#This Row],[Column57]] -> 449085 | BF4: =FF_PX[[#This Row],[Column58]] -> 428730 | BG4: =FF_PX[[#This Row],[Column59]] -> 404961 | BH4: =FF_PX[[#This Row],[Column60]] -> 409169 | BI4: =FF_PX[[#This Row],[Column61]] -> 403830 | BJ4: =FF_PX[[#This Row],[Column62]] -> 391063 | BK4: =FF_PX[[#This Row],[Column63]] -> 360566 | BL4: =FF_PX[[#This Row],[Column64]] -> 340749 | BM4: =FF_PX[[#This Row],[Column65]] -> 328478 | BN4: =FF_PX[[#This Row],[Column66]] -> 330255 | BO4: =FF_PX[[#This Row],[Column67]] -> 332947 | BP4: =FF_PX[[#This Row],[Column68]] -> 254738 | BQ4: =FF_PX[[#This Row],[Column69]] -> 245226 | BR4: =FF_PX[[#This Row],[Column70]] -> 248182 | BS4: =FF_PX[[#This Row],[Column71]] -> 247782 | BT4: =FF_PX[[#This Row],[Column72]] -> 245311 | BU4: =FF_PX[[#This Row],[Column73]] -> 242987 | BV4: =FF_PX[[#This Row],[Column74]] -> 240472 | BW4: =FF_PX[[#This Row],[Column75]] -> 240756 | BX4: =FF_PX[[#This Row],[Column76]] -> 239176 | BY4: =FF_PX[[#This Row],[Column77]] -> 243419 | BZ4: =FF_PX[[#This Row],[Column78]] -> 243419 | CA4: =FF_PX[[#This Row],[Column79]] -> 244670 | CB4: =FF_PX[[#This Row],[Column80]] -> 242210 | CC4: =FF_PX[[#This Row],[Column81]] -> 224479 | CD4: =FF_PX[[#This Row],[Column82]] -> 214657 | CE4: =FF_PX[[#This Row],[Column83]] -> 214606 | CF4: =FF_PX[[#This Row],[Column84]] -> 210446 | CG4: =FF_PX[[#This Row],[Column85]] -> 203374 | CH4: =FF_PX[[#This Row],[Column86]] -> 198232 | CI4: =FF_PX[[#This Row],[Column87]] -> 201233 | CJ4: =FF_PX[[#This Row],[Column88]] -> 535806 | CK4: =FF_PX[[#This Row],[Column89]] -> 524616 | CL4: =FF_PX[[#This Row],[Column90]] -> 541586 | CM4: =FF_PX[[#This Row],[Column91]] -> 586400 | CN4: =FF_PX[[#This Row],[Column92]] -> 591267 | CO4: =FF_PX[[#This Row],[Column93]] -> 589586 | CP4: =FF_PX[[#This Row],[Column94]] -> 586302 | CQ4: =FF_PX[[#This Row],[Column95]] -> 585464 | CR4: =FF_PX[[#This Row],[Column96]] -> 588496 | CS4: =FF_PX[[#This Row],[Column97]] -> 598143 | CT4: =FF_PX[[#This Row],[Column98]] -> 598143 | CU4: =FF_PX[[#This Row],[Column99]] -> 598284 | CV4: =FF_PX[[#This Row],[Column100]] -> 607935 | CW4: =FF_PX[[#This Row],[Column101]] -> 588301 | CX4: =FF_PX[[#This Row],[Column102]] -> 646598 | CY4: =FF_PX[[#This Row],[Column103]] -> 648922 | CZ4: =FF_PX[[#This Row],[Column104]] -> 698820 | DA4: =FF_PX[[#This Row],[Column105]] -> 691795
A5: ='cont list_0'!M8 -> Q26 | B5: =FF_PX[[#This Row],[Column2]] -> 300668 | C5: =FF_PX[[#This Row],[Column3]] -> 300668 | D5: =FF_PX[[#This Row],[Column4]] -> 304948 | E5: =FF_PX[[#This Row],[Column5]] -> 295703 | F5: =FF_PX[[#This Row],[Column6]] -> 296314 | G5: =FF_PX[[#This Row],[Column7]] -> 297152 | H5: =FF_PX[[#This Row],[Column8]] -> 297152 | I5: =FF_PX[[#This Row],[Column9]] -> 289312 | J5: =FF_PX[[#This Row],[Column10]] -> 289148 | K5: =FF_PX[[#This Row],[Column11]] -> 291788 | L5: =FF_PX[[#This Row],[Column12]] -> 274982 | M5: =FF_PX[[#This Row],[Column13]] -> 254664 | N5: =FF_PX[[#This Row],[Column14]] -> 252122 | O5: =FF_PX[[#This Row],[Column15]] -> 262634 | P5: =FF_PX[[#This Row],[Column16]] -> 251886 | Q5: =FF_PX[[#This Row],[Column17]] -> 250517 | R5: =FF_PX[[#This Row],[Column18]] -> 252634 | S5: =FF_PX[[#This Row],[Column19]] -> 240372 | T5: =FF_PX[[#This Row],[Column20]] -> 232062 | U5: =FF_PX[[#This Row],[Column21]] -> 211023 | V5: =FF_PX[[#This Row],[Column22]] -> 206918 | W5: =FF_PX[[#This Row],[Column23]] -> 206565 | X5: =FF_PX[[#This Row],[Column24]] -> 217838 | Y5: =FF_PX[[#This Row],[Column25]] -> 222988 | Z5: =FF_PX[[#This Row],[Column26]] -> 210388 | AA5: =FF_PX[[#This Row],[Column27]] -> 210921 | AB5: =FF_PX[[#This Row],[Column28]] -> 211990 | AC5: =FF_PX[[#This Row],[Column29]] -> 211685 | AD5: =FF_PX[[#This Row],[Column30]] -> 197990 | AE5: =FF_PX[[#This Row],[Column31]] -> 197976 | AF5: =FF_PX[[#This Row],[Column32]] -> 211713 | AG5: =FF_PX[[#This Row],[Column33]] -> 210820 | AH5: =FF_PX[[#This Row],[Column34]] -> 206702 | AI5: =FF_PX[[#This Row],[Column35]] -> 206539 | AJ5: =FF_PX[[#This Row],[Column36]] -> 199499 | AK5: =FF_PX[[#This Row],[Column37]] -> 194553 | AL5: =FF_PX[[#This Row],[Column38]] -> 190006 | AM5: =FF_PX[[#This Row],[Column39]] -> 188876 | AN5: =FF_PX[[#This Row],[Column40]] -> 187508 | AO5: =FF_PX[[#This Row],[Column41]] -> 190733 | AP5: =FF_PX[[#This Row],[Column42]] -> 189011 | AQ5: =FF_PX[[#This Row],[Column43]] -> 192259 | AR5: =FF_PX[[#This Row],[Column44]] -> 192497 | AS5: =FF_PX[[#This Row],[Column45]] -> 193891 | AT5: =FF_PX[[#This Row],[Column46]] -> 467845 | AU5: =FF_PX[[#This Row],[Column47]] -> 460427 | AV5: =FF_PX[[#This Row],[Column48]] -> 448906 | AW5: =FF_PX[[#This Row],[Column49]] -> 461884 | AX5: =FF_PX[[#This Row],[Column50]] -> 454246 | AY5: =FF_PX[[#This Row],[Column51]] -> 458996 | AZ5: =FF_PX[[#This Row],[Column52]] -> 458390 | BA5: =FF_PX[[#This Row],[Column53]] -> 458699 | BB5: =FF_PX[[#This Row],[Column54]] -> 433299 | BC5: =FF_PX[[#This Row],[Column55]] -> 402069 | BD5: =FF_PX[[#This Row],[Column56]] -> 370745 | BE5: =FF_PX[[#This Row],[Column57]] -> 368707 | BF5: =FF_PX[[#This Row],[Column58]] -> 376699 | BG5: =FF_PX[[#This Row],[Column59]] -> 362584 | BH5: =FF_PX[[#This Row],[Column60]] -> 367266 | BI5: =FF_PX[[#This Row],[Column61]] -> 363874 | BJ5: =FF_PX[[#This Row],[Column62]] -> 351425 | BK5: =FF_PX[[#This Row],[Column63]] -> 365862 | BL5: =FF_PX[[#This Row],[Column64]] -> 367350 | BM5: =FF_PX[[#This Row],[Column65]] -> 371082 | BN5: =FF_PX[[#This Row],[Column66]] -> 373924 | BO5: =FF_PX[[#This Row],[Column67]] -> 399034 | BP5: =FF_PX[[#This Row],[Column68]] -> 330655 | BQ5: =FF_PX[[#This Row],[Column69]] -> 322070 | BR5: =FF_PX[[#This Row],[Column70]] -> 311847 | BS5: =FF_PX[[#This Row],[Column71]] -> 312771 | BT5: =FF_PX[[#This Row],[Column72]] -> 309698 | BU5: =FF_PX[[#This Row],[Column73]] -> 289883 | BV5: =FF_PX[[#This Row],[Column74]] -> 277632 | BW5: =FF_PX[[#This Row],[Column75]] -> 277153 | BX5: =FF_PX[[#This Row],[Column76]] -> 277371 | BY5: =FF_PX[[#This Row],[Column77]] -> 278891 | BZ5: =FF_PX[[#This Row],[Column78]] -> 278891 | CA5: =FF_PX[[#This Row],[Column79]] -> 275058 | CB5: =FF_PX[[#This Row],[Column80]] -> 280130 | CC5: =FF_PX[[#This Row],[Column81]] -> 284247 | CD5: =FF_PX[[#This Row],[Column82]] -> 284907 | CE5: =FF_PX[[#This Row],[Column83]] -> 276947 | CF5: =FF_PX[[#This Row],[Column84]] -> 267296 | CG5: =FF_PX[[#This Row],[Column85]] -> 257319 | CH5: =FF_PX[[#This Row],[Column86]] -> 259826 | CI5: =FF_PX[[#This Row],[Column87]] -> 262871 | CJ5: =FF_PX[[#This Row],[Column88]] -> 200038 | CK5: =FF_PX[[#This Row],[Column89]] -> 198176 | CL5: =FF_PX[[#This Row],[Column90]] -> 198404 | CM5: =FF_PX[[#This Row],[Column91]] -> 195468 | CN5: =FF_PX[[#This Row],[Column92]] -> 196075 | CO5: =FF_PX[[#This Row],[Column93]] -> 195684 | CP5: =FF_PX[[#This Row],[Column94]] -> 198118 | CQ5: =FF_PX[[#This Row],[Column95]] -> 199038 | CR5: =FF_PX[[#This Row],[Column96]] -> 195646 | CS5: =FF_PX[[#This Row],[Column97]] -> 192264 | CT5: =FF_PX[[#This Row],[Column98]] -> 192264 | CU5: =FF_PX[[#This Row],[Column99]] -> 190069 | CV5: =FF_PX[[#This Row],[Column100]] -> 190810 | CW5: =FF_PX[[#This Row],[Column101]] -> 188399 | CX5: =FF_PX[[#This Row],[Column102]] -> 193326 | CY5: =FF_PX[[#This Row],[Column103]] -> 196870 | CZ5: =FF_PX[[#This Row],[Column104]] -> 202303 | DA5: =FF_PX[[#This Row],[Column105]] -> 202243
A6: ='cont list_0'!M9 -> U26 | B6: =FF_PX[[#This Row],[Column2]] -> 320372 | C6: =FF_PX[[#This Row],[Column3]] -> 320372 | D6: =FF_PX[[#This Row],[Column4]] -> 308047 | E6: =FF_PX[[#This Row],[Column5]] -> 301101 | F6: =FF_PX[[#This Row],[Column6]] -> 303811 | G6: =FF_PX[[#This Row],[Column7]] -> 308189 | H6: =FF_PX[[#This Row],[Column8]] -> 308189 | I6: =FF_PX[[#This Row],[Column9]] -> 289112 | J6: =FF_PX[[#This Row],[Column10]] -> 300027 | K6: =FF_PX[[#This Row],[Column11]] -> 288909 | L6: =FF_PX[[#This Row],[Column12]] -> 271887 | M6: =FF_PX[[#This Row],[Column13]] -> 267664 | N6: =FF_PX[[#This Row],[Column14]] -> 265742 | O6: =FF_PX[[#This Row],[Column15]] -> 253772 | P6: =FF_PX[[#This Row],[Column16]] -> 246301 | Q6: =FF_PX[[#This Row],[Column17]] -> 243014 | R6: =FF_PX[[#This Row],[Column18]] -> 237744 | S6: =FF_PX[[#This Row],[Column19]] -> 236028 | T6: =FF_PX[[#This Row],[Column20]] -> 233387 | U6: =FF_PX[[#This Row],[Column21]] -> 207868 | V6: =FF_PX[[#This Row],[Column22]] -> 202945 | W6: =FF_PX[[#This Row],[Column23]] -> 198872 | X6: =FF_PX[[#This Row],[Column24]] -> 205353 | Y6: =FF_PX[[#This Row],[Column25]] -> 203618 | Z6: =FF_PX[[#This Row],[Column26]] -> 202701 | AA6: =FF_PX[[#This Row],[Column27]] -> 203867 | AB6: =FF_PX[[#This Row],[Column28]] -> 190806 | AC6: =FF_PX[[#This Row],[Column29]] -> 188514 | AD6: =FF_PX[[#This Row],[Column30]] -> 187937 | AE6: =FF_PX[[#This Row],[Column31]] -> 186553 | AF6: =FF_PX[[#This Row],[Column32]] -> 188053 | AG6: =FF_PX[[#This Row],[Column33]] -> 189482 | AH6: =FF_PX[[#This Row],[Column34]] -> 193364 | AI6: =FF_PX[[#This Row],[Column35]] -> 195528 | AJ6: =FF_PX[[#This Row],[Column36]] -> 196648 | AK6: =FF_PX[[#This Row],[Column37]] -> 197839 | AL6: =FF_PX[[#This Row],[Column38]] -> 193885 | AM6: =FF_PX[[#This Row],[Column39]] -> 195849 | AN6: =FF_PX[[#This Row],[Column40]] -> 201288 | AO6: =FF_PX[[#This Row],[Column41]] -> 198336 | AP6: =FF_PX[[#This Row],[Column42]] -> 196863 | AQ6: =FF_PX[[#This Row],[Column43]] -> 198003 | AR6: =FF_PX[[#This Row],[Column44]] -> 193864 | AS6: =FF_PX[[#This Row],[Column45]] -> 192641 | AT6: =FF_PX[[#This Row],[Column46]] -> 192884 | AU6: =FF_PX[[#This Row],[Column47]] -> 194928 | AV6: =FF_PX[[#This Row],[Column48]] -> 194378 | AW6: =FF_PX[[#This Row],[Column49]] -> 198198 | AX6: =FF_PX[[#This Row],[Column50]] -> 207139 | AY6: =FF_PX[[#This Row],[Column51]] -> 209876 | AZ6: =FF_PX[[#This Row],[Column52]] -> 210735 | BA6: =FF_PX[[#This Row],[Column53]] -> 217106 | BB6: =FF_PX[[#This Row],[Column54]] -> 217213 | BC6: =FF_PX[[#This Row],[Column55]] -> 216283 | BD6: =FF_PX[[#This Row],[Column56]] -> 212198 | BE6: =FF_PX[[#This Row],[Column57]] -> 209476 | BF6: =FF_PX[[#This Row],[Column58]] -> 202234 | BG6: =FF_PX[[#This Row],[Column59]] -> 198790 | BH6: =FF_PX[[#This Row],[Column60]] -> 194678 | BI6: =FF_PX[[#This Row],[Column61]] -> 192068 | BJ6: =FF_PX[[#This Row],[Column62]] -> 187518 | BK6: =FF_PX[[#This Row],[Column63]] -> 187829 | BL6: =FF_PX[[#This Row],[Column64]] -> 192239 | BM6: =FF_PX[[#This Row],[Column65]] -> 191741 | BN6: =FF_PX[[#This Row],[Column66]] -> 191518 | BO6: =FF_PX[[#This Row],[Column67]] -> 189907 | BP6: =FF_PX[[#This Row],[Column68]] -> 410686 | BQ6: =FF_PX[[#This Row],[Column69]] -> 389923 | BR6: =FF_PX[[#This Row],[Column70]] -> 366932 | BS6: =FF_PX[[#This Row],[Column71]] -> 365587 | BT6: =FF_PX[[#This Row],[Column72]] -> 366898 | BU6: =FF_PX[[#This Row],[Column73]] -> 398893 | BV6: =FF_PX[[#This Row],[Column74]] -> 388112 | BW6: =FF_PX[[#This Row],[Column75]] -> 368952 | BX6: =FF_PX[[#This Row],[Column76]] -> 354604 | BY6: =FF_PX[[#This Row],[Column77]] -> 334749 | BZ6: =FF_PX[[#This Row],[Column78]] -> 334749 | CA6: =FF_PX[[#This Row],[Column79]] -> 319802 | CB6: =FF_PX[[#This Row],[Column80]] -> 310218 | CC6: =FF_PX[[#This Row],[Column81]] -> 291410 | CD6: =FF_PX[[#This Row],[Column82]] -> 296886 | CE6: =FF_PX[[#This Row],[Column83]] -> 287056 | CF6: =FF_PX[[#This Row],[Column84]] -> 294807 | CG6: =FF_PX[[#This Row],[Column85]] -> 275080 | CH6: =FF_PX[[#This Row],[Column86]] -> 276531 | CI6: =FF_PX[[#This Row],[Column87]] -> 277687 | CJ6: =FF_PX[[#This Row],[Column88]] -> 273089 | CK6: =FF_PX[[#This Row],[Column89]] -> 268234 | CL6: =FF_PX[[#This Row],[Column90]] -> 260661 | CM6: =FF_PX[[#This Row],[Column91]] -> 253864 | CN6: =FF_PX[[#This Row],[Column92]] -> 250231 | CO6: =FF_PX[[#This Row],[Column93]] -> 251699 | CP6: =FF_PX[[#This Row],[Column94]] -> 254102 | CQ6: =FF_PX[[#This Row],[Column95]] -> 246632 | CR6: =FF_PX[[#This Row],[Column96]] -> 243851 | CS6: =FF_PX[[#This Row],[Column97]] -> 247975 | CT6: =FF_PX[[#This Row],[Column98]] -> 247975 | CU6: =FF_PX[[#This Row],[Column99]] -> 233296 | CV6: =FF_PX[[#This Row],[Column100]] -> 201542 | CW6: =FF_PX[[#This Row],[Column101]] -> 199118 | CX6: =FF_PX[[#This Row],[Column102]] -> 195872 | CY6: =FF_PX[[#This Row],[Column103]] -> 193950 | CZ6: =FF_PX[[#This Row],[Column104]] -> 180890 | DA6: =FF_PX[[#This Row],[Column105]] -> 179456
