Workbook

Sheet SR3
A2: =SOFR3mo_PX[[#This Row],[Column1]] -> Dates | B2: =SOFR3mo_PX[[#This Row],[Column2]] -> 46302 | C2: =SOFR3mo_PX[[#This Row],[Column3]] -> 46301 | D2: =SOFR3mo_PX[[#This Row],[Column4]] -> 46300 | E2: =SOFR3mo_PX[[#This Row],[Column5]] -> 46297 | F2: =SOFR3mo_PX[[#This Row],[Column6]] -> 46296 | G2: =SOFR3mo_PX[[#This Row],[Column7]] -> 46295 | H2: =SOFR3mo_PX[[#This Row],[Column8]] -> 46294 | I2: =SOFR3mo_PX[[#This Row],[Column9]] -> 46293 | J2: =SOFR3mo_PX[[#This Row],[Column10]] -> 46290 | K2: =SOFR3mo_PX[[#This Row],[Column11]] -> 46289 | L2: =SOFR3mo_PX[[#This Row],[Column12]] -> 46288 | M2: =SOFR3mo_PX[[#This Row],[Column13]] -> 46287 | N2: =SOFR3mo_PX[[#This Row],[Column14]] -> 46286 | O2: =SOFR3mo_PX[[#This Row],[Column15]] -> 46283 | P2: =SOFR3mo_PX[[#This Row],[Column16]] -> 46282 | Q2: =SOFR3mo_PX[[#This Row],[Column17]] -> 46281 | R2: =SOFR3mo_PX[[#This Row],[Column18]] -> 46280 | S2: =SOFR3mo_PX[[#This Row],[Column19]] -> 46279 | T2: =SOFR3mo_PX[[#This Row],[Column20]] -> 46276 | U2: =SOFR3mo_PX[[#This Row],[Column21]] -> 46275 | V2: =SOFR3mo_PX[[#This Row],[Column22]] -> 46274 | W2: =SOFR3mo_PX[[#This Row],[Column23]] -> 46273 | X2: =SOFR3mo_PX[[#This Row],[Column24]] -> 46272 | Y2: =SOFR3mo_PX[[#This Row],[Column25]] -> 46269 | Z2: =SOFR3mo_PX[[#This Row],[Column26]] -> 46268 | AA2: =SOFR3mo_PX[[#This Row],[Column27]] -> 46267 | AB2: =SOFR3mo_PX[[#This Row],[Column28]] -> 46266 | AC2: =SOFR3mo_PX[[#This Row],[Column29]] -> 46265 | AD2: =SOFR3mo_PX[[#This Row],[Column30]] -> 46262 | AE2: =SOFR3mo_PX[[#This Row],[Column31]] -> 46261 | AF2: =SOFR3mo_PX[[#This Row],[Column32]] -> 46260 | AG2: =SOFR3mo_PX[[#This Row],[Column33]] -> 46259 | AH2: =SOFR3mo_PX[[#This Row],[Column34]] -> 46258 | AI2: =SOFR3mo_PX[[#This Row],[Column35]] -> 46255 | AJ2: =SOFR3mo_PX[[#This Row],[Column36]] -> 46254 | AK2: =SOFR3mo_PX[[#This Row],[Column37]] -> 46253 | AL2: =SOFR3mo_PX[[#This Row],[Column38]] -> 46252 | AM2: =SOFR3mo_PX[[#This Row],[Column39]] -> 46251 | AN2: =SOFR3mo_PX[[#This Row],[Column40]] -> 46248 | AO2: =SOFR3mo_PX[[#This Row],[Column41]] -> 46247 | AP2: =SOFR3mo_PX[[#This Row],[Column42]] -> 46246 | AQ2: =SOFR3mo_PX[[#This Row],[Column43]] -> 46245 | AR2: =SOFR3mo_PX[[#This Row],[Column44]] -> 46244 | AS2: =SOFR3mo_PX[[#This Row],[Column45]] -> 46241 | AT2: =SOFR3mo_PX[[#This Row],[Column46]] -> 46240 | AU2: =SOFR3mo_PX[[#This Row],[Column47]] -> 46239 | AV2: =SOFR3mo_PX[[#This Row],[Column48]] -> 46238 | AW2: =SOFR3mo_PX[[#This Row],[Column49]] -> 46237 | AX2: =SOFR3mo_PX[[#This Row],[Column50]] -> 46234 | AY2: =SOFR3mo_PX[[#This Row],[Column51]] -> 46233 | AZ2: =SOFR3mo_PX[[#This Row],[Column52]] -> 46232 | BA2: =SOFR3mo_PX[[#This Row],[Column53]] -> 46231 | BB2: =SOFR3mo_PX[[#This Row],[Column54]] -> 46230 | BC2: =SOFR3mo_PX[[#This Row],[Column55]] -> 46227 | BD2: =SOFR3mo_PX[[#This Row],[Column56]] -> 46226 | BE2: =SOFR3mo_PX[[#This Row],[Column57]] -> 46225 | BF2: =SOFR3mo_PX[[#This Row],[Column58]] -> 46224 | BG2: =SOFR3mo_PX[[#This Row],[Column59]] -> 46223 | BH2: =SOFR3mo_PX[[#This Row],[Column60]] -> 46220 | BI2: =SOFR3mo_PX[[#This Row],[Column61]] -> 46219 | BJ2: =SOFR3mo_PX[[#This Row],[Column62]] -> 46218 | BK2: =SOFR3mo_PX[[#This Row],[Column63]] -> 46217 | BL2: =SOFR3mo_PX[[#This Row],[Column64]] -> 46216 | BM2: =SOFR3mo_PX[[#This Row],[Column65]] -> 46213 | BN2: =SOFR3mo_PX[[#This Row],[Column66]] -> 46212 | BO2: =SOFR3mo_PX[[#This Row],[Column67]] -> 46211 | BP2: =SOFR3mo_PX[[#This Row],[Column68]] -> 46210 | BQ2: =SOFR3mo_PX[[#This Row],[Column69]] -> 46209 | BR2: =SOFR3mo_PX[[#This Row],[Column70]] -> 46206 | BS2: =SOFR3mo_PX[[#This Row],[Column71]] -> 46205 | BT2: =SOFR3mo_PX[[#This Row],[Column72]] -> 46204 | BU2: =SOFR3mo_PX[[#This Row],[Column73]] -> 46203 | BV2: =SOFR3mo_PX[[#This Row],[Column74]] -> 46202 | BW2: =SOFR3mo_PX[[#This Row],[Column75]] -> 46199 | BX2: =SOFR3mo_PX[[#This Row],[Column76]] -> 46198 | BY2: =SOFR3mo_PX[[#This Row],[Column77]] -> 46197 | BZ2: =SOFR3mo_PX[[#This Row],[Column78]] -> 46196 | CA2: =SOFR3mo_PX[[#This Row],[Column79]] -> 46195 | CB2: =SOFR3mo_PX[[#This Row],[Column80]] -> 46192 | CC2: =SOFR3mo_PX[[#This Row],[Column81]] -> 46191 | CD2: =SOFR3mo_PX[[#This Row],[Column82]] -> 46190 | CE2: =SOFR3mo_PX[[#This Row],[Column83]] -> 46189 | CF2: =SOFR3mo_PX[[#This Row],[Column84]] -> 46188 | CG2: =SOFR3mo_PX[[#This Row],[Column85]] -> 46185 | CH2: =SOFR3mo_PX[[#This Row],[Column86]] -> 46184 | CI2: =SOFR3mo_PX[[#This Row],[Column87]] -> 46183 | CJ2: =SOFR3mo_PX[[#This Row],[Column88]] -> 46182 | CK2: =SOFR3mo_PX[[#This Row],[Column89]] -> 46181 | CL2: =SOFR3mo_PX[[#This Row],[Column90]] -> 46178 | CM2: =SOFR3mo_PX[[#This Row],[Column91]] -> 46177
A3: ='cont list_0'!I6 -> U26 | B3: =SOFR3mo_PX[[#This Row],[Column2]] -> 1313010 | C3: =SOFR3mo_PX[[#This Row],[Column3]] -> 1313010 | D3: =SOFR3mo_PX[[#This Row],[Column4]] -> 1322577 | E3: =SOFR3mo_PX[[#This Row],[Column5]] -> 1336046 | F3: =SOFR3mo_PX[[#This Row],[Column6]] -> 1337217 | G3: =SOFR3mo_PX[[#This Row],[Column7]] -> 1369880 | H3: =SOFR3mo_PX[[#This Row],[Column8]] -> 1361416 | I3: =SOFR3mo_PX[[#This Row],[Column9]] -> 1335525 | J3: =SOFR3mo_PX[[#This Row],[Column10]] -> 1348782 | K3: =SOFR3mo_PX[[#This Row],[Column11]] -> 1335557 | L3: =SOFR3mo_PX[[#This Row],[Column12]] -> 1322564 | M3: =SOFR3mo_PX[[#This Row],[Column13]] -> 1306563 | N3: =SOFR3mo_PX[[#This Row],[Column14]] -> 1302004 | O3: =SOFR3mo_PX[[#This Row],[Column15]] -> 1285672 | P3: =SOFR3mo_PX[[#This Row],[Column16]] -> 1298884 | Q3: =SOFR3mo_PX[[#This Row],[Column17]] -> 1342184 | R3: =SOFR3mo_PX[[#This Row],[Column18]] -> 1328928 | S3: =SOFR3mo_PX[[#This Row],[Column19]] -> 1341164 | T3: =SOFR3mo_PX[[#This Row],[Column20]] -> 1340535 | U3: =SOFR3mo_PX[[#This Row],[Column21]] -> 1349516 | V3: =SOFR3mo_PX[[#This Row],[Column22]] -> 1319105 | W3: =SOFR3mo_PX[[#This Row],[Column23]] -> 1328556 | X3: =SOFR3mo_PX[[#This Row],[Column24]] -> 1335309 | Y3: =SOFR3mo_PX[[#This Row],[Column25]] -> 1334979 | Z3: =SOFR3mo_PX[[#This Row],[Column26]] -> 1346256 | AA3: =SOFR3mo_PX[[#This Row],[Column27]] -> 1346111 | AB3: =SOFR3mo_PX[[#This Row],[Column28]] -> 1364634 | AC3: =SOFR3mo_PX[[#This Row],[Column29]] -> 1343413 | AD3: =SOFR3mo_PX[[#This Row],[Column30]] -> 1340956 | AE3: =SOFR3mo_PX[[#This Row],[Column31]] -> 1326680 | AF3: =SOFR3mo_PX[[#This Row],[Column32]] -> 1345176 | AG3: =SOFR3mo_PX[[#This Row],[Column33]] -> 1317019 | AH3: =SOFR3mo_PX[[#This Row],[Column34]] -> 1314716 | AI3: =SOFR3mo_PX[[#This Row],[Column35]] -> 1316208 | AJ3: =SOFR3mo_PX[[#This Row],[Column36]] -> 1310645 | AK3: =SOFR3mo_PX[[#This Row],[Column37]] -> 1324966 | AL3: =SOFR3mo_PX[[#This Row],[Column38]] -> 1356281 | AM3: =SOFR3mo_PX[[#This Row],[Column39]] -> 1309392 | AN3: =SOFR3mo_PX[[#This Row],[Column40]] -> 1313571 | AO3: =SOFR3mo_PX[[#This Row],[Column41]] -> 1321988 | AP3: =SOFR3mo_PX[[#This Row],[Column42]] -> 1316520 | AQ3: =SOFR3mo_PX[[#This Row],[Column43]] -> 1311921 | AR3: =SOFR3mo_PX[[#This Row],[Column44]] -> 1287877 | AS3: =SOFR3mo_PX[[#This Row],[Column45]] -> 1288217 | AT3: =SOFR3mo_PX[[#This Row],[Column46]] -> 1307968 | AU3: =SOFR3mo_PX[[#This Row],[Column47]] -> 1300369 | AV3: =SOFR3mo_PX[[#This Row],[Column48]] -> 1307606 | AW3: =SOFR3mo_PX[[#This Row],[Column49]] -> 1289312 | AX3: =SOFR3mo_PX[[#This Row],[Column50]] -> 1301081 | AY3: =SOFR3mo_PX[[#This Row],[Column51]] -> 1263532 | AZ3: =SOFR3mo_PX[[#This Row],[Column52]] -> 1292934 | BA3: =SOFR3mo_PX[[#This Row],[Column53]] -> 1242998 | BB3: =SOFR3mo_PX[[#This Row],[Column54]] -> 1288621 | BC3: =SOFR3mo_PX[[#This Row],[Column55]] -> 1276108 | BD3: =SOFR3mo_PX[[#This Row],[Column56]] -> 1264084 | BE3: =SOFR3mo_PX[[#This Row],[Column57]] -> 1263307 | BF3: =SOFR3mo_PX[[#This Row],[Column58]] -> 1260348 | BG3: =SOFR3mo_PX[[#This Row],[Column59]] -> 1282235 | BH3: =SOFR3mo_PX[[#This Row],[Column60]] -> 1267997 | BI3: =SOFR3mo_PX[[#This Row],[Column61]] -> 1284349 | BJ3: =SOFR3mo_PX[[#This Row],[Column62]] -> 1304048 | BK3: =SOFR3mo_PX[[#This Row],[Column63]] -> 1274334 | BL3: =SOFR3mo_PX[[#This Row],[Column64]] -> 1267727 | BM3: =SOFR3mo_PX[[#This Row],[Column65]] -> 1299859 | BN3: =SOFR3mo_PX[[#This Row],[Column66]] -> 1318936 | BO3: =SOFR3mo_PX[[#This Row],[Column67]] -> 1310945 | BP3: =SOFR3mo_PX[[#This Row],[Column68]] -> 1301102 | BQ3: =SOFR3mo_PX[[#This Row],[Column69]] -> 1287294 | BR3: =SOFR3mo_PX[[#This Row],[Column70]] -> 1294403 | BS3: =SOFR3mo_PX[[#This Row],[Column71]] -> 1289283 | BT3: =SOFR3mo_PX[[#This Row],[Column72]] -> 1295407 | BU3: =SOFR3mo_PX[[#This Row],[Column73]] -> 1303149 | BV3: =SOFR3mo_PX[[#This Row],[Column74]] -> 1323173 | BW3: =SOFR3mo_PX[[#This Row],[Column75]] -> 1329909 | BX3: =SOFR3mo_PX[[#This Row],[Column76]] -> 1320930 | BY3: =SOFR3mo_PX[[#This Row],[Column77]] -> 1327310 | BZ3: =SOFR3mo_PX[[#This Row],[Column78]] -> 1323016 | CA3: =SOFR3mo_PX[[#This Row],[Column79]] -> 1346603 | CB3: =SOFR3mo_PX[[#This Row],[Column80]] -> 1340889 | CC3: =SOFR3mo_PX[[#This Row],[Column81]] -> 1338568 | CD3: =SOFR3mo_PX[[#This Row],[Column82]] -> 1361498 | CE3: =SOFR3mo_PX[[#This Row],[Column83]] -> 1300215 | CF3: =SOFR3mo_PX[[#This Row],[Column84]] -> 1299563 | CG3: =SOFR3mo_PX[[#This Row],[Column85]] -> 1306538 | CH3: =SOFR3mo_PX[[#This Row],[Column86]] -> 1279547 | CI3: =SOFR3mo_PX[[#This Row],[Column87]] -> 1280782 | CJ3: =SOFR3mo_PX[[#This Row],[Column88]] -> 1282174 | CK3: =SOFR3mo_PX[[#This Row],[Column89]] -> 1296629 | CL3: =SOFR3mo_PX[[#This Row],[Column90]] -> 1286801 | CM3: =SOFR3mo_PX[[#This Row],[Column91]] -> 1291288
A4: ='cont list_0'!I7 -> Z26 | B4: =SOFR3mo_PX[[#This Row],[Column2]] -> 1589081 | C4: =SOFR3mo_PX[[#This Row],[Column3]] -> 1589081 | D4: =SOFR3mo_PX[[#This Row],[Column4]] -> 1606404 | E4: =SOFR3mo_PX[[#This Row],[Column5]] -> 1604509 | F4: =SOFR3mo_PX[[#This Row],[Column6]] -> 1586424 | G4: =SOFR3mo_PX[[#This Row],[Column7]] -> 1668021 | H4: =SOFR3mo_PX[[#This Row],[Column8]] -> 1680008 | I4: =SOFR3mo_PX[[#This Row],[Column9]] -> 1673715 | J4: =SOFR3mo_PX[[#This Row],[Column10]] -> 1670000 | K4: =SOFR3mo_PX[[#This Row],[Column11]] -> 1667494 | L4: =SOFR3mo_PX[[#This Row],[Column12]] -> 1655322 | M4: =SOFR3mo_PX[[#This Row],[Column13]] -> 1631934 | N4: =SOFR3mo_PX[[#This Row],[Column14]] -> 1629657 | O4: =SOFR3mo_PX[[#This Row],[Column15]] -> 1651929 | P4: =SOFR3mo_PX[[#This Row],[Column16]] -> 1673585 | Q4: =SOFR3mo_PX[[#This Row],[Column17]] -> 1651721 | R4: =SOFR3mo_PX[[#This Row],[Column18]] -> 1319566 | S4: =SOFR3mo_PX[[#This Row],[Column19]] -> 1322497 | T4: =SOFR3mo_PX[[#This Row],[Column20]] -> 1304520 | U4: =SOFR3mo_PX[[#This Row],[Column21]] -> 1358557 | V4: =SOFR3mo_PX[[#This Row],[Column22]] -> 1393184 | W4: =SOFR3mo_PX[[#This Row],[Column23]] -> 1394881 | X4: =SOFR3mo_PX[[#This Row],[Column24]] -> 1373315 | Y4: =SOFR3mo_PX[[#This Row],[Column25]] -> 1380530 | Z4: =SOFR3mo_PX[[#This Row],[Column26]] -> 1348233 | AA4: =SOFR3mo_PX[[#This Row],[Column27]] -> 1332497 | AB4: =SOFR3mo_PX[[#This Row],[Column28]] -> 1300514 | AC4: =SOFR3mo_PX[[#This Row],[Column29]] -> 1294961 | AD4: =SOFR3mo_PX[[#This Row],[Column30]] -> 1270143 | AE4: =SOFR3mo_PX[[#This Row],[Column31]] -> 1284968 | AF4: =SOFR3mo_PX[[#This Row],[Column32]] -> 1272122 | AG4: =SOFR3mo_PX[[#This Row],[Column33]] -> 1246513 | AH4: =SOFR3mo_PX[[#This Row],[Column34]] -> 1249966 | AI4: =SOFR3mo_PX[[#This Row],[Column35]] -> 1277298 | AJ4: =SOFR3mo_PX[[#This Row],[Column36]] -> 1272851 | AK4: =SOFR3mo_PX[[#This Row],[Column37]] -> 1313234 | AL4: =SOFR3mo_PX[[#This Row],[Column38]] -> 1368816 | AM4: =SOFR3mo_PX[[#This Row],[Column39]] -> 1339200 | AN4: =SOFR3mo_PX[[#This Row],[Column40]] -> 1353699 | AO4: =SOFR3mo_PX[[#This Row],[Column41]] -> 1414737 | AP4: =SOFR3mo_PX[[#This Row],[Column42]] -> 1402860 | AQ4: =SOFR3mo_PX[[#This Row],[Column43]] -> 1370843 | AR4: =SOFR3mo_PX[[#This Row],[Column44]] -> 1368161 | AS4: =SOFR3mo_PX[[#This Row],[Column45]] -> 1352236 | AT4: =SOFR3mo_PX[[#This Row],[Column46]] -> 1375966 | AU4: =SOFR3mo_PX[[#This Row],[Column47]] -> 1406850 | AV4: =SOFR3mo_PX[[#This Row],[Column48]] -> 1430546 | AW4: =SOFR3mo_PX[[#This Row],[Column49]] -> 1413692 | AX4: =SOFR3mo_PX[[#This Row],[Column50]] -> 1410856 | AY4: =SOFR3mo_PX[[#This Row],[Column51]] -> 1368583 | AZ4: =SOFR3mo_PX[[#This Row],[Column52]] -> 1353348 | BA4: =SOFR3mo_PX[[#This Row],[Column53]] -> 1331089 | BB4: =SOFR3mo_PX[[#This Row],[Column54]] -> 1358762 | BC4: =SOFR3mo_PX[[#This Row],[Column55]] -> 1367038 | BD4: =SOFR3mo_PX[[#This Row],[Column56]] -> 1378658 | BE4: =SOFR3mo_PX[[#This Row],[Column57]] -> 1387820 | BF4: =SOFR3mo_PX[[#This Row],[Column58]] -> 1394235 | BG4: =SOFR3mo_PX[[#This Row],[Column59]] -> 1410008 | BH4: =SOFR3mo_PX[[#This Row],[Column60]] -> 1425759 | BI4: =SOFR3mo_PX[[#This Row],[Column61]] -> 1437566 | BJ4: =SOFR3mo_PX[[#This Row],[Column62]] -> 1429570 | BK4: =SOFR3mo_PX[[#This Row],[Column63]] -> 1455536 | BL4: =SOFR3mo_PX[[#This Row],[Column64]] -> 1495318 | BM4: =SOFR3mo_PX[[#This Row],[Column65]] -> 1500238 | BN4: =SOFR3mo_PX[[#This Row],[Column66]] -> 1460012 | BO4: =SOFR3mo_PX[[#This Row],[Column67]] -> 1470902 | BP4: =SOFR3mo_PX[[#This Row],[Column68]] -> 1465954 | BQ4: =SOFR3mo_PX[[#This Row],[Column69]] -> 1484929 | BR4: =SOFR3mo_PX[[#This Row],[Column70]] -> 1498069 | BS4: =SOFR3mo_PX[[#This Row],[Column71]] -> 1482620 | BT4: =SOFR3mo_PX[[#This Row],[Column72]] -> 1504916 | BU4: =SOFR3mo_PX[[#This Row],[Column73]] -> 1474565 | BV4: =SOFR3mo_PX[[#This Row],[Column74]] -> 1449601 | BW4: =SOFR3mo_PX[[#This Row],[Column75]] -> 1455089 | BX4: =SOFR3mo_PX[[#This Row],[Column76]] -> 1467115 | BY4: =SOFR3mo_PX[[#This Row],[Column77]] -> 1468357 | BZ4: =SOFR3mo_PX[[#This Row],[Column78]] -> 1482918 | CA4: =SOFR3mo_PX[[#This Row],[Column79]] -> 1509921 | CB4: =SOFR3mo_PX[[#This Row],[Column80]] -> 1515294 | CC4: =SOFR3mo_PX[[#This Row],[Column81]] -> 1548136 | CD4: =SOFR3mo_PX[[#This Row],[Column82]] -> 1532002 | CE4: =SOFR3mo_PX[[#This Row],[Column83]] -> 1451904 | CF4: =SOFR3mo_PX[[#This Row],[Column84]] -> 1430644 | CG4: =SOFR3mo_PX[[#This Row],[Column85]] -> 1372687 | CH4: =SOFR3mo_PX[[#This Row],[Column86]] -> 1399166 | CI4: =SOFR3mo_PX[[#This Row],[Column87]] -> 1405587 | CJ4: =SOFR3mo_PX[[#This Row],[Column88]] -> 1387920 | CK4: =SOFR3mo_PX[[#This Row],[Column89]] -> 1379309 | CL4: =SOFR3mo_PX[[#This Row],[Column90]] -> 1382254 | CM4: =SOFR3mo_PX[[#This Row],[Column91]] -> 1375572
A5: ='cont list_0'!I8 -> H27 | B5: =SOFR3mo_PX[[#This Row],[Column2]] -> 1258932 | C5: =SOFR3mo_PX[[#This Row],[Column3]] -> 1258932 | D5: =SOFR3mo_PX[[#This Row],[Column4]] -> 1227015 | E5: =SOFR3mo_PX[[#This Row],[Column5]] -> 1240535 | F5: =SOFR3mo_PX[[#This Row],[Column6]] -> 1208242 | G5: =SOFR3mo_PX[[#This Row],[Column7]] -> 1186643 | H5: =SOFR3mo_PX[[#This Row],[Column8]] -> 1194802 | I5: =SOFR3mo_PX[[#This Row],[Column9]] -> 1192021 | J5: =SOFR3mo_PX[[#This Row],[Column10]] -> 1173592 | K5: =SOFR3mo_PX[[#This Row],[Column11]] -> 1187919 | L5: =SOFR3mo_PX[[#This Row],[Column12]] -> 1207136 | M5: =SOFR3mo_PX[[#This Row],[Column13]] -> 1192259 | N5: =SOFR3mo_PX[[#This Row],[Column14]] -> 1184280 | O5: =SOFR3mo_PX[[#This Row],[Column15]] -> 1208142 | P5: =SOFR3mo_PX[[#This Row],[Column16]] -> 1212305 | Q5: =SOFR3mo_PX[[#This Row],[Column17]] -> 1215336 | R5: =SOFR3mo_PX[[#This Row],[Column18]] -> 1656075 | S5: =SOFR3mo_PX[[#This Row],[Column19]] -> 1673904 | T5: =SOFR3mo_PX[[#This Row],[Column20]] -> 1670349 | U5: =SOFR3mo_PX[[#This Row],[Column21]] -> 1705255 | V5: =SOFR3mo_PX[[#This Row],[Column22]] -> 1719408 | W5: =SOFR3mo_PX[[#This Row],[Column23]] -> 1748297 | X5: =SOFR3mo_PX[[#This Row],[Column24]] -> 1742223 | Y5: =SOFR3mo_PX[[#This Row],[Column25]] -> 1742114 | Z5: =SOFR3mo_PX[[#This Row],[Column26]] -> 1747144 | AA5: =SOFR3mo_PX[[#This Row],[Column27]] -> 1751424 | AB5: =SOFR3mo_PX[[#This Row],[Column28]] -> 1750135 | AC5: =SOFR3mo_PX[[#This Row],[Column29]] -> 1736388 | AD5: =SOFR3mo_PX[[#This Row],[Column30]] -> 1757566 | AE5: =SOFR3mo_PX[[#This Row],[Column31]] -> 1739871 | AF5: =SOFR3mo_PX[[#This Row],[Column32]] -> 1726698 | AG5: =SOFR3mo_PX[[#This Row],[Column33]] -> 1721663 | AH5: =SOFR3mo_PX[[#This Row],[Column34]] -> 1708743 | AI5: =SOFR3mo_PX[[#This Row],[Column35]] -> 1701817 | AJ5: =SOFR3mo_PX[[#This Row],[Column36]] -> 1691819 | AK5: =SOFR3mo_PX[[#This Row],[Column37]] -> 1686445 | AL5: =SOFR3mo_PX[[#This Row],[Column38]] -> 1744057 | AM5: =SOFR3mo_PX[[#This Row],[Column39]] -> 1692475 | AN5: =SOFR3mo_PX[[#This Row],[Column40]] -> 1704711 | AO5: =SOFR3mo_PX[[#This Row],[Column41]] -> 1712993 | AP5: =SOFR3mo_PX[[#This Row],[Column42]] -> 1732680 | AQ5: =SOFR3mo_PX[[#This Row],[Column43]] -> 1743392 | AR5: =SOFR3mo_PX[[#This Row],[Column44]] -> 1764187 | AS5: =SOFR3mo_PX[[#This Row],[Column45]] -> 1745093 | AT5: =SOFR3mo_PX[[#This Row],[Column46]] -> 1729546 | AU5: =SOFR3mo_PX[[#This Row],[Column47]] -> 1714534 | AV5: =SOFR3mo_PX[[#This Row],[Column48]] -> 1713870 | AW5: =SOFR3mo_PX[[#This Row],[Column49]] -> 1710605 | AX5: =SOFR3mo_PX[[#This Row],[Column50]] -> 1682422 | AY5: =SOFR3mo_PX[[#This Row],[Column51]] -> 1661532 | AZ5: =SOFR3mo_PX[[#This Row],[Column52]] -> 1687952 | BA5: =SOFR3mo_PX[[#This Row],[Column53]] -> 1721989 | BB5: =SOFR3mo_PX[[#This Row],[Column54]] -> 1755858 | BC5: =SOFR3mo_PX[[#This Row],[Column55]] -> 1731035 | BD5: =SOFR3mo_PX[[#This Row],[Column56]] -> 1729366 | BE5: =SOFR3mo_PX[[#This Row],[Column57]] -> 1782692 | BF5: =SOFR3mo_PX[[#This Row],[Column58]] -> 1839053 | BG5: =SOFR3mo_PX[[#This Row],[Column59]] -> 1825540 | BH5: =SOFR3mo_PX[[#This Row],[Column60]] -> 1826697 | BI5: =SOFR3mo_PX[[#This Row],[Column61]] -> 1814564 | BJ5: =SOFR3mo_PX[[#This Row],[Column62]] -> 1799075 | BK5: =SOFR3mo_PX[[#This Row],[Column63]] -> 1807378 | BL5: =SOFR3mo_PX[[#This Row],[Column64]] -> 1825920 | BM5: =SOFR3mo_PX[[#This Row],[Column65]] -> 1799317 | BN5: =SOFR3mo_PX[[#This Row],[Column66]] -> 1797599 | BO5: =SOFR3mo_PX[[#This Row],[Column67]] -> 1790208 | BP5: =SOFR3mo_PX[[#This Row],[Column68]] -> 1791905 | BQ5: =SOFR3mo_PX[[#This Row],[Column69]] -> 1783687 | BR5: =SOFR3mo_PX[[#This Row],[Column70]] -> 1782227 | BS5: =SOFR3mo_PX[[#This Row],[Column71]] -> 1780756 | BT5: =SOFR3mo_PX[[#This Row],[Column72]] -> 1788582 | BU5: =SOFR3mo_PX[[#This Row],[Column73]] -> 1817855 | BV5: =SOFR3mo_PX[[#This Row],[Column74]] -> 1814578 | BW5: =SOFR3mo_PX[[#This Row],[Column75]] -> 1825485 | BX5: =SOFR3mo_PX[[#This Row],[Column76]] -> 1811791 | BY5: =SOFR3mo_PX[[#This Row],[Column77]] -> 1785000 | BZ5: =SOFR3mo_PX[[#This Row],[Column78]] -> 1756334 | CA5: =SOFR3mo_PX[[#This Row],[Column79]] -> 1750857 | CB5: =SOFR3mo_PX[[#This Row],[Column80]] -> 1750266 | CC5: =SOFR3mo_PX[[#This Row],[Column81]] -> 1745071 | CD5: =SOFR3mo_PX[[#This Row],[Column82]] -> 1787585 | CE5: =SOFR3mo_PX[[#This Row],[Column83]] -> 1503884 | CF5: =SOFR3mo_PX[[#This Row],[Column84]] -> 1490888 | CG5: =SOFR3mo_PX[[#This Row],[Column85]] -> 1459572 | CH5: =SOFR3mo_PX[[#This Row],[Column86]] -> 1458258 | CI5: =SOFR3mo_PX[[#This Row],[Column87]] -> 1461509 | CJ5: =SOFR3mo_PX[[#This Row],[Column88]] -> 1474438 | CK5: =SOFR3mo_PX[[#This Row],[Column89]] -> 1486080 | CL5: =SOFR3mo_PX[[#This Row],[Column90]] -> 1516392 | CM5: =SOFR3mo_PX[[#This Row],[Column91]] -> 1499636
A6: ='cont list_0'!I9 -> M27 | B6: =SOFR3mo_PX[[#This Row],[Column2]] -> 1266828 | C6: =SOFR3mo_PX[[#This Row],[Column3]] -> 1266828 | D6: =SOFR3mo_PX[[#This Row],[Column4]] -> 1255333 | E6: =SOFR3mo_PX[[#This Row],[Column5]] -> 1240852 | F6: =SOFR3mo_PX[[#This Row],[Column6]] -> 1217552 | G6: =SOFR3mo_PX[[#This Row],[Column7]] -> 1274554 | H6: =SOFR3mo_PX[[#This Row],[Column8]] -> 1278458 | I6: =SOFR3mo_PX[[#This Row],[Column9]] -> 1260920 | J6: =SOFR3mo_PX[[#This Row],[Column10]] -> 1251198 | K6: =SOFR3mo_PX[[#This Row],[Column11]] -> 1236403 | L6: =SOFR3mo_PX[[#This Row],[Column12]] -> 1254171 | M6: =SOFR3mo_PX[[#This Row],[Column13]] -> 1272592 | N6: =SOFR3mo_PX[[#This Row],[Column14]] -> 1257227 | O6: =SOFR3mo_PX[[#This Row],[Column15]] -> 1260279 | P6: =SOFR3mo_PX[[#This Row],[Column16]] -> 1291996 | Q6: =SOFR3mo_PX[[#This Row],[Column17]] -> 1290385 | R6: =SOFR3mo_PX[[#This Row],[Column18]] -> 1133386 | S6: =SOFR3mo_PX[[#This Row],[Column19]] -> 1123726 | T6: =SOFR3mo_PX[[#This Row],[Column20]] -> 1133254 | U6: =SOFR3mo_PX[[#This Row],[Column21]] -> 1134170 | V6: =SOFR3mo_PX[[#This Row],[Column22]] -> 1123094 | W6: =SOFR3mo_PX[[#This Row],[Column23]] -> 1120543 | X6: =SOFR3mo_PX[[#This Row],[Column24]] -> 1124623 | Y6: =SOFR3mo_PX[[#This Row],[Column25]] -> 1124621 | Z6: =SOFR3mo_PX[[#This Row],[Column26]] -> 1131305 | AA6: =SOFR3mo_PX[[#This Row],[Column27]] -> 1122662 | AB6: =SOFR3mo_PX[[#This Row],[Column28]] -> 1105301 | AC6: =SOFR3mo_PX[[#This Row],[Column29]] -> 1134279 | AD6: =SOFR3mo_PX[[#This Row],[Column30]] -> 1112953 | AE6: =SOFR3mo_PX[[#This Row],[Column31]] -> 1111143 | AF6: =SOFR3mo_PX[[#This Row],[Column32]] -> 1106567 | AG6: =SOFR3mo_PX[[#This Row],[Column33]] -> 1092215 | AH6: =SOFR3mo_PX[[#This Row],[Column34]] -> 1093170 | AI6: =SOFR3mo_PX[[#This Row],[Column35]] -> 1089871 | AJ6: =SOFR3mo_PX[[#This Row],[Column36]] -> 1079955 | AK6: =SOFR3mo_PX[[#This Row],[Column37]] -> 1073925 | AL6: =SOFR3mo_PX[[#This Row],[Column38]] -> 1111859 | AM6: =SOFR3mo_PX[[#This Row],[Column39]] -> 1078999 | AN6: =SOFR3mo_PX[[#This Row],[Column40]] -> 1073660 | AO6: =SOFR3mo_PX[[#This Row],[Column41]] -> 1075359 | AP6: =SOFR3mo_PX[[#This Row],[Column42]] -> 1077141 | AQ6: =SOFR3mo_PX[[#This Row],[Column43]] -> 1074005 | AR6: =SOFR3mo_PX[[#This Row],[Column44]] -> 1079655 | AS6: =SOFR3mo_PX[[#This Row],[Column45]] -> 1081633 | AT6: =SOFR3mo_PX[[#This Row],[Column46]] -> 1089906 | AU6: =SOFR3mo_PX[[#This Row],[Column47]] -> 1083614 | AV6: =SOFR3mo_PX[[#This Row],[Column48]] -> 1072918 | AW6: =SOFR3mo_PX[[#This Row],[Column49]] -> 1075474 | AX6: =SOFR3mo_PX[[#This Row],[Column50]] -> 1064793 | AY6: =SOFR3mo_PX[[#This Row],[Column51]] -> 1061557 | AZ6: =SOFR3mo_PX[[#This Row],[Column52]] -> 1051834 | BA6: =SOFR3mo_PX[[#This Row],[Column53]] -> 1070847 | BB6: =SOFR3mo_PX[[#This Row],[Column54]] -> 1088129 | BC6: =SOFR3mo_PX[[#This Row],[Column55]] -> 1099611 | BD6: =SOFR3mo_PX[[#This Row],[Column56]] -> 1107903 | BE6: =SOFR3mo_PX[[#This Row],[Column57]] -> 1123372 | BF6: =SOFR3mo_PX[[#This Row],[Column58]] -> 1133481 | BG6: =SOFR3mo_PX[[#This Row],[Column59]] -> 1119324 | BH6: =SOFR3mo_PX[[#This Row],[Column60]] -> 1123500 | BI6: =SOFR3mo_PX[[#This Row],[Column61]] -> 1144414 | BJ6: =SOFR3mo_PX[[#This Row],[Column62]] -> 1159035 | BK6: =SOFR3mo_PX[[#This Row],[Column63]] -> 1169799 | BL6: =SOFR3mo_PX[[#This Row],[Column64]] -> 1204950 | BM6: =SOFR3mo_PX[[#This Row],[Column65]] -> 1191586 | BN6: =SOFR3mo_PX[[#This Row],[Column66]] -> 1190020 | BO6: =SOFR3mo_PX[[#This Row],[Column67]] -> 1168902 | BP6: =SOFR3mo_PX[[#This Row],[Column68]] -> 1157002 | BQ6: =SOFR3mo_PX[[#This Row],[Column69]] -> 1151649 | BR6: =SOFR3mo_PX[[#This Row],[Column70]] -> 1155497 | BS6: =SOFR3mo_PX[[#This Row],[Column71]] -> 1146502 | BT6: =SOFR3mo_PX[[#This Row],[Column72]] -> 1113033 | BU6: =SOFR3mo_PX[[#This Row],[Column73]] -> 1135287 | BV6: =SOFR3mo_PX[[#This Row],[Column74]] -> 1138372 | BW6: =SOFR3mo_PX[[#This Row],[Column75]] -> 1134084 | BX6: =SOFR3mo_PX[[#This Row],[Column76]] -> 1101586 | BY6: =SOFR3mo_PX[[#This Row],[Column77]] -> 1086500 | BZ6: =SOFR3mo_PX[[#This Row],[Column78]] -> 1086752 | CA6: =SOFR3mo_PX[[#This Row],[Column79]] -> 1115927 | CB6: =SOFR3mo_PX[[#This Row],[Column80]] -> 1121390 | CC6: =SOFR3mo_PX[[#This Row],[Column81]] -> 1125009 | CD6: =SOFR3mo_PX[[#This Row],[Column82]] -> 1135714 | CE6: =SOFR3mo_PX[[#This Row],[Column83]] -> 1729885 | CF6: =SOFR3mo_PX[[#This Row],[Column84]] -> 1667736 | CG6: =SOFR3mo_PX[[#This Row],[Column85]] -> 1625208 | CH6: =SOFR3mo_PX[[#This Row],[Column86]] -> 1611873 | CI6: =SOFR3mo_PX[[#This Row],[Column87]] -> 1585496 | CJ6: =SOFR3mo_PX[[#This Row],[Column88]] -> 1600436 | CK6: =SOFR3mo_PX[[#This Row],[Column89]] -> 1613113 | CL6: =SOFR3mo_PX[[#This Row],[Column90]] -> 1602923 | CM6: =SOFR3mo_PX[[#This Row],[Column91]] -> 1594953
A7: ='cont list_0'!I10 -> U27 | B7: =SOFR3mo_PX[[#This Row],[Column2]] -> 1032737 | C7: =SOFR3mo_PX[[#This Row],[Column3]] -> 1032737 | D7: =SOFR3mo_PX[[#This Row],[Column4]] -> 1025807 | E7: =SOFR3mo_PX[[#This Row],[Column5]] -> 1018057 | F7: =SOFR3mo_PX[[#This Row],[Column6]] -> 1000261 | G7: =SOFR3mo_PX[[#This Row],[Column7]] -> 1002462 | H7: =SOFR3mo_PX[[#This Row],[Column8]] -> 988747 | I7: =SOFR3mo_PX[[#This Row],[Column9]] -> 978893 | J7: =SOFR3mo_PX[[#This Row],[Column10]] -> 962990 | K7: =SOFR3mo_PX[[#This Row],[Column11]] -> 971509 | L7: =SOFR3mo_PX[[#This Row],[Column12]] -> 968298 | M7: =SOFR3mo_PX[[#This Row],[Column13]] -> 940834 | N7: =SOFR3mo_PX[[#This Row],[Column14]] -> 943623 | O7: =SOFR3mo_PX[[#This Row],[Column15]] -> 929860 | P7: =SOFR3mo_PX[[#This Row],[Column16]] -> 940079 | Q7: =SOFR3mo_PX[[#This Row],[Column17]] -> 950909 | R7: =SOFR3mo_PX[[#This Row],[Column18]] -> 1232048 | S7: =SOFR3mo_PX[[#This Row],[Column19]] -> 1229976 | T7: =SOFR3mo_PX[[#This Row],[Column20]] -> 1208289 | U7: =SOFR3mo_PX[[#This Row],[Column21]] -> 1194668 | V7: =SOFR3mo_PX[[#This Row],[Column22]] -> 1183781 | W7: =SOFR3mo_PX[[#This Row],[Column23]] -> 1182968 | X7: =SOFR3mo_PX[[#This Row],[Column24]] -> 1193204 | Y7: =SOFR3mo_PX[[#This Row],[Column25]] -> 1193205 | Z7: =SOFR3mo_PX[[#This Row],[Column26]] -> 1197713 | AA7: =SOFR3mo_PX[[#This Row],[Column27]] -> 1194537 | AB7: =SOFR3mo_PX[[#This Row],[Column28]] -> 1179688 | AC7: =SOFR3mo_PX[[#This Row],[Column29]] -> 1197654 | AD7: =SOFR3mo_PX[[#This Row],[Column30]] -> 1199251 | AE7: =SOFR3mo_PX[[#This Row],[Column31]] -> 1202049 | AF7: =SOFR3mo_PX[[#This Row],[Column32]] -> 1204840 | AG7: =SOFR3mo_PX[[#This Row],[Column33]] -> 1191516 | AH7: =SOFR3mo_PX[[#This Row],[Column34]] -> 1188353 | AI7: =SOFR3mo_PX[[#This Row],[Column35]] -> 1197555 | AJ7: =SOFR3mo_PX[[#This Row],[Column36]] -> 1189647 | AK7: =SOFR3mo_PX[[#This Row],[Column37]] -> 1178941 | AL7: =SOFR3mo_PX[[#This Row],[Column38]] -> 1233665 | AM7: =SOFR3mo_PX[[#This Row],[Column39]] -> 1185272 | AN7: =SOFR3mo_PX[[#This Row],[Column40]] -> 1185056 | AO7: =SOFR3mo_PX[[#This Row],[Column41]] -> 1191862 | AP7: =SOFR3mo_PX[[#This Row],[Column42]] -> 1220869 | AQ7: =SOFR3mo_PX[[#This Row],[Column43]] -> 1218446 | AR7: =SOFR3mo_PX[[#This Row],[Column44]] -> 1223841 | AS7: =SOFR3mo_PX[[#This Row],[Column45]] -> 1220427 | AT7: =SOFR3mo_PX[[#This Row],[Column46]] -> 1224037 | AU7: =SOFR3mo_PX[[#This Row],[Column47]] -> 1224281 | AV7: =SOFR3mo_PX[[#This Row],[Column48]] -> 1223141 | AW7: =SOFR3mo_PX[[#This Row],[Column49]] -> 1219117 | AX7: =SOFR3mo_PX[[#This Row],[Column50]] -> 1179088 | AY7: =SOFR3mo_PX[[#This Row],[Column51]] -> 1156782 | AZ7: =SOFR3mo_PX[[#This Row],[Column52]] -> 1156250 | BA7: =SOFR3mo_PX[[#This Row],[Column53]] -> 1163826 | BB7: =SOFR3mo_PX[[#This Row],[Column54]] -> 1173353 | BC7: =SOFR3mo_PX[[#This Row],[Column55]] -> 1178203 | BD7: =SOFR3mo_PX[[#This Row],[Column56]] -> 1192351 | BE7: =SOFR3mo_PX[[#This Row],[Column57]] -> 1206179 | BF7: =SOFR3mo_PX[[#This Row],[Column58]] -> 1202723 | BG7: =SOFR3mo_PX[[#This Row],[Column59]] -> 1202111 | BH7: =SOFR3mo_PX[[#This Row],[Column60]] -> 1216792 | BI7: =SOFR3mo_PX[[#This Row],[Column61]] -> 1235226 | BJ7: =SOFR3mo_PX[[#This Row],[Column62]] -> 1232067 | BK7: =SOFR3mo_PX[[#This Row],[Column63]] -> 1248758 | BL7: =SOFR3mo_PX[[#This Row],[Column64]] -> 1263926 | BM7: =SOFR3mo_PX[[#This Row],[Column65]] -> 1254056 | BN7: =SOFR3mo_PX[[#This Row],[Column66]] -> 1260699 | BO7: =SOFR3mo_PX[[#This Row],[Column67]] -> 1254697 | BP7: =SOFR3mo_PX[[#This Row],[Column68]] -> 1282854 | BQ7: =SOFR3mo_PX[[#This Row],[Column69]] -> 1280860 | BR7: =SOFR3mo_PX[[#This Row],[Column70]] -> 1296432 | BS7: =SOFR3mo_PX[[#This Row],[Column71]] -> 1273287 | BT7: =SOFR3mo_PX[[#This Row],[Column72]] -> 1269562 | BU7: =SOFR3mo_PX[[#This Row],[Column73]] -> 1282776 | BV7: =SOFR3mo_PX[[#This Row],[Column74]] -> 1265987 | BW7: =SOFR3mo_PX[[#This Row],[Column75]] -> 1265052 | BX7: =SOFR3mo_PX[[#This Row],[Column76]] -> 1233431 | BY7: =SOFR3mo_PX[[#This Row],[Column77]] -> 1189239 | BZ7: =SOFR3mo_PX[[#This Row],[Column78]] -> 1196367 | CA7: =SOFR3mo_PX[[#This Row],[Column79]] -> 1206680 | CB7: =SOFR3mo_PX[[#This Row],[Column80]] -> 1199705 | CC7: =SOFR3mo_PX[[#This Row],[Column81]] -> 1201741 | CD7: =SOFR3mo_PX[[#This Row],[Column82]] -> 1215781 | CE7: =SOFR3mo_PX[[#This Row],[Column83]] -> 1080953 | CF7: =SOFR3mo_PX[[#This Row],[Column84]] -> 1067106 | CG7: =SOFR3mo_PX[[#This Row],[Column85]] -> 1067209 | CH7: =SOFR3mo_PX[[#This Row],[Column86]] -> 1061690 | CI7: =SOFR3mo_PX[[#This Row],[Column87]] -> 1059518 | CJ7: =SOFR3mo_PX[[#This Row],[Column88]] -> 1058635 | CK7: =SOFR3mo_PX[[#This Row],[Column89]] -> 1069589 | CL7: =SOFR3mo_PX[[#This Row],[Column90]] -> 1060874 | CM7: =SOFR3mo_PX[[#This Row],[Column91]] -> 1068276
A8: ='cont list_0'!I11 -> Z27 | B8: =SOFR3mo_PX[[#This Row],[Column2]] -> 1547587 | C8: =SOFR3mo_PX[[#This Row],[Column3]] -> 1547587 | D8: =SOFR3mo_PX[[#This Row],[Column4]] -> 1534904 | E8: =SOFR3mo_PX[[#This Row],[Column5]] -> 1528552 | F8: =SOFR3mo_PX[[#This Row],[Column6]] -> 1502839 | G8: =SOFR3mo_PX[[#This Row],[Column7]] -> 1489764 | H8: =SOFR3mo_PX[[#This Row],[Column8]] -> 1470484 | I8: =SOFR3mo_PX[[#This Row],[Column9]] -> 1465477 | J8: =SOFR3mo_PX[[#This Row],[Column10]] -> 1455648 | K8: =SOFR3mo_PX[[#This Row],[Column11]] -> 1429883 | L8: =SOFR3mo_PX[[#This Row],[Column12]] -> 1433151 | M8: =SOFR3mo_PX[[#This Row],[Column13]] -> 1424925 | N8: =SOFR3mo_PX[[#This Row],[Column14]] -> 1410736 | O8: =SOFR3mo_PX[[#This Row],[Column15]] -> 1412352 | P8: =SOFR3mo_PX[[#This Row],[Column16]] -> 1440259 | Q8: =SOFR3mo_PX[[#This Row],[Column17]] -> 1444496 | R8: =SOFR3mo_PX[[#This Row],[Column18]] -> 944073 | S8: =SOFR3mo_PX[[#This Row],[Column19]] -> 957816 | T8: =SOFR3mo_PX[[#This Row],[Column20]] -> 964462 | U8: =SOFR3mo_PX[[#This Row],[Column21]] -> 942988 | V8: =SOFR3mo_PX[[#This Row],[Column22]] -> 940882 | W8: =SOFR3mo_PX[[#This Row],[Column23]] -> 945455 | X8: =SOFR3mo_PX[[#This Row],[Column24]] -> 936474 | Y8: =SOFR3mo_PX[[#This Row],[Column25]] -> 942442 | Z8: =SOFR3mo_PX[[#This Row],[Column26]] -> 927368 | AA8: =SOFR3mo_PX[[#This Row],[Column27]] -> 909115 | AB8: =SOFR3mo_PX[[#This Row],[Column28]] -> 910768 | AC8: =SOFR3mo_PX[[#This Row],[Column29]] -> 907093 | AD8: =SOFR3mo_PX[[#This Row],[Column30]] -> 908627 | AE8: =SOFR3mo_PX[[#This Row],[Column31]] -> 895985 | AF8: =SOFR3mo_PX[[#This Row],[Column32]] -> 901258 | AG8: =SOFR3mo_PX[[#This Row],[Column33]] -> 902336 | AH8: =SOFR3mo_PX[[#This Row],[Column34]] -> 908989 | AI8: =SOFR3mo_PX[[#This Row],[Column35]] -> 902794 | AJ8: =SOFR3mo_PX[[#This Row],[Column36]] -> 890588 | AK8: =SOFR3mo_PX[[#This Row],[Column37]] -> 897337 | AL8: =SOFR3mo_PX[[#This Row],[Column38]] -> 923844 | AM8: =SOFR3mo_PX[[#This Row],[Column39]] -> 891499 | AN8: =SOFR3mo_PX[[#This Row],[Column40]] -> 894816 | AO8: =SOFR3mo_PX[[#This Row],[Column41]] -> 898716 | AP8: =SOFR3mo_PX[[#This Row],[Column42]] -> 902164 | AQ8: =SOFR3mo_PX[[#This Row],[Column43]] -> 911907 | AR8: =SOFR3mo_PX[[#This Row],[Column44]] -> 917989 | AS8: =SOFR3mo_PX[[#This Row],[Column45]] -> 918696 | AT8: =SOFR3mo_PX[[#This Row],[Column46]] -> 926760 | AU8: =SOFR3mo_PX[[#This Row],[Column47]] -> 924261 | AV8: =SOFR3mo_PX[[#This Row],[Column48]] -> 922126 | AW8: =SOFR3mo_PX[[#This Row],[Column49]] -> 924366 | AX8: =SOFR3mo_PX[[#This Row],[Column50]] -> 924785 | AY8: =SOFR3mo_PX[[#This Row],[Column51]] -> 902330 | AZ8: =SOFR3mo_PX[[#This Row],[Column52]] -> 911292 | BA8: =SOFR3mo_PX[[#This Row],[Column53]] -> 929060 | BB8: =SOFR3mo_PX[[#This Row],[Column54]] -> 928726 | BC8: =SOFR3mo_PX[[#This Row],[Column55]] -> 926888 | BD8: =SOFR3mo_PX[[#This Row],[Column56]] -> 941982 | BE8: =SOFR3mo_PX[[#This Row],[Column57]] -> 928163 | BF8: =SOFR3mo_PX[[#This Row],[Column58]] -> 934224 | BG8: =SOFR3mo_PX[[#This Row],[Column59]] -> 927024 | BH8: =SOFR3mo_PX[[#This Row],[Column60]] -> 933755 | BI8: =SOFR3mo_PX[[#This Row],[Column61]] -> 946364 | BJ8: =SOFR3mo_PX[[#This Row],[Column62]] -> 964812 | BK8: =SOFR3mo_PX[[#This Row],[Column63]] -> 962731 | BL8: =SOFR3mo_PX[[#This Row],[Column64]] -> 965569 | BM8: =SOFR3mo_PX[[#This Row],[Column65]] -> 950017 | BN8: =SOFR3mo_PX[[#This Row],[Column66]] -> 939494 | BO8: =SOFR3mo_PX[[#This Row],[Column67]] -> 942983 | BP8: =SOFR3mo_PX[[#This Row],[Column68]] -> 968718 | BQ8: =SOFR3mo_PX[[#This Row],[Column69]] -> 964111 | BR8: =SOFR3mo_PX[[#This Row],[Column70]] -> 980539 | BS8: =SOFR3mo_PX[[#This Row],[Column71]] -> 960139 | BT8: =SOFR3mo_PX[[#This Row],[Column72]] -> 962609 | BU8: =SOFR3mo_PX[[#This Row],[Column73]] -> 965165 | BV8: =SOFR3mo_PX[[#This Row],[Column74]] -> 950198 | BW8: =SOFR3mo_PX[[#This Row],[Column75]] -> 947802 | BX8: =SOFR3mo_PX[[#This Row],[Column76]] -> 956841 | BY8: =SOFR3mo_PX[[#This Row],[Column77]] -> 898207 | BZ8: =SOFR3mo_PX[[#This Row],[Column78]] -> 896402 | CA8: =SOFR3mo_PX[[#This Row],[Column79]] -> 903524 | CB8: =SOFR3mo_PX[[#This Row],[Column80]] -> 882932 | CC8: =SOFR3mo_PX[[#This Row],[Column81]] -> 904288 | CD8: =SOFR3mo_PX[[#This Row],[Column82]] -> 896281 | CE8: =SOFR3mo_PX[[#This Row],[Column83]] -> 1207760 | CF8: =SOFR3mo_PX[[#This Row],[Column84]] -> 1209008 | CG8: =SOFR3mo_PX[[#This Row],[Column85]] -> 1237784 | CH8: =SOFR3mo_PX[[#This Row],[Column86]] -> 1206003 | CI8: =SOFR3mo_PX[[#This Row],[Column87]] -> 1221015 | CJ8: =SOFR3mo_PX[[#This Row],[Column88]] -> 1212687 | CK8: =SOFR3mo_PX[[#This Row],[Column89]] -> 1219584 | CL8: =SOFR3mo_PX[[#This Row],[Column90]] -> 1193111 | CM8: =SOFR3mo_PX[[#This Row],[Column91]] -> 1199145
A9: ='cont list_0'!I12 -> H28 | B9: =SOFR3mo_PX[[#This Row],[Column2]] -> 803766 | C9: =SOFR3mo_PX[[#This Row],[Column3]] -> 803766 | D9: =SOFR3mo_PX[[#This Row],[Column4]] -> 789606 | E9: =SOFR3mo_PX[[#This Row],[Column5]] -> 779832 | F9: =SOFR3mo_PX[[#This Row],[Column6]] -> 770966 | G9: =SOFR3mo_PX[[#This Row],[Column7]] -> 759713 | H9: =SOFR3mo_PX[[#This Row],[Column8]] -> 751116 | I9: =SOFR3mo_PX[[#This Row],[Column9]] -> 734489 | J9: =SOFR3mo_PX[[#This Row],[Column10]] -> 713752 | K9: =SOFR3mo_PX[[#This Row],[Column11]] -> 729791 | L9: =SOFR3mo_PX[[#This Row],[Column12]] -> 719173 | M9: =SOFR3mo_PX[[#This Row],[Column13]] -> 723328 | N9: =SOFR3mo_PX[[#This Row],[Column14]] -> 712568 | O9: =SOFR3mo_PX[[#This Row],[Column15]] -> 710358 | P9: =SOFR3mo_PX[[#This Row],[Column16]] -> 714106 | Q9: =SOFR3mo_PX[[#This Row],[Column17]] -> 709098 | R9: =SOFR3mo_PX[[#This Row],[Column18]] -> 1412980 | S9: =SOFR3mo_PX[[#This Row],[Column19]] -> 1405710 | T9: =SOFR3mo_PX[[#This Row],[Column20]] -> 1392560 | U9: =SOFR3mo_PX[[#This Row],[Column21]] -> 1400590 | V9: =SOFR3mo_PX[[#This Row],[Column22]] -> 1378573 | W9: =SOFR3mo_PX[[#This Row],[Column23]] -> 1382309 | X9: =SOFR3mo_PX[[#This Row],[Column24]] -> 1386738 | Y9: =SOFR3mo_PX[[#This Row],[Column25]] -> 1386738 | Z9: =SOFR3mo_PX[[#This Row],[Column26]] -> 1371278 | AA9: =SOFR3mo_PX[[#This Row],[Column27]] -> 1351680 | AB9: =SOFR3mo_PX[[#This Row],[Column28]] -> 1348146 | AC9: =SOFR3mo_PX[[#This Row],[Column29]] -> 1325115 | AD9: =SOFR3mo_PX[[#This Row],[Column30]] -> 1320469 | AE9: =SOFR3mo_PX[[#This Row],[Column31]] -> 1315368 | AF9: =SOFR3mo_PX[[#This Row],[Column32]] -> 1338432 | AG9: =SOFR3mo_PX[[#This Row],[Column33]] -> 1357395 | AH9: =SOFR3mo_PX[[#This Row],[Column34]] -> 1373170 | AI9: =SOFR3mo_PX[[#This Row],[Column35]] -> 1362010 | AJ9: =SOFR3mo_PX[[#This Row],[Column36]] -> 1378746 | AK9: =SOFR3mo_PX[[#This Row],[Column37]] -> 1381529 | AL9: =SOFR3mo_PX[[#This Row],[Column38]] -> 1367659 | AM9: =SOFR3mo_PX[[#This Row],[Column39]] -> 1349414 | AN9: =SOFR3mo_PX[[#This Row],[Column40]] -> 1344578 | AO9: =SOFR3mo_PX[[#This Row],[Column41]] -> 1347106 | AP9: =SOFR3mo_PX[[#This Row],[Column42]] -> 1362154 | AQ9: =SOFR3mo_PX[[#This Row],[Column43]] -> 1341745 | AR9: =SOFR3mo_PX[[#This Row],[Column44]] -> 1353584 | AS9: =SOFR3mo_PX[[#This Row],[Column45]] -> 1345706 | AT9: =SOFR3mo_PX[[#This Row],[Column46]] -> 1343733 | AU9: =SOFR3mo_PX[[#This Row],[Column47]] -> 1333596 | AV9: =SOFR3mo_PX[[#This Row],[Column48]] -> 1323215 | AW9: =SOFR3mo_PX[[#This Row],[Column49]] -> 1308309 | AX9: =SOFR3mo_PX[[#This Row],[Column50]] -> 1283577 | AY9: =SOFR3mo_PX[[#This Row],[Column51]] -> 1264904 | AZ9: =SOFR3mo_PX[[#This Row],[Column52]] -> 1298364 | BA9: =SOFR3mo_PX[[#This Row],[Column53]] -> 1311643 | BB9: =SOFR3mo_PX[[#This Row],[Column54]] -> 1324100 | BC9: =SOFR3mo_PX[[#This Row],[Column55]] -> 1329257 | BD9: =SOFR3mo_PX[[#This Row],[Column56]] -> 1313650 | BE9: =SOFR3mo_PX[[#This Row],[Column57]] -> 1279040 | BF9: =SOFR3mo_PX[[#This Row],[Column58]] -> 1284565 | BG9: =SOFR3mo_PX[[#This Row],[Column59]] -> 1244218 | BH9: =SOFR3mo_PX[[#This Row],[Column60]] -> 1237092 | BI9: =SOFR3mo_PX[[#This Row],[Column61]] -> 1250468 | BJ9: =SOFR3mo_PX[[#This Row],[Column62]] -> 1243106 | BK9: =SOFR3mo_PX[[#This Row],[Column63]] -> 1251901 | BL9: =SOFR3mo_PX[[#This Row],[Column64]] -> 1264462 | BM9: =SOFR3mo_PX[[#This Row],[Column65]] -> 1225964 | BN9: =SOFR3mo_PX[[#This Row],[Column66]] -> 1225074 | BO9: =SOFR3mo_PX[[#This Row],[Column67]] -> 1223034 | BP9: =SOFR3mo_PX[[#This Row],[Column68]] -> 1213830 | BQ9: =SOFR3mo_PX[[#This Row],[Column69]] -> 1210342 | BR9: =SOFR3mo_PX[[#This Row],[Column70]] -> 1205081 | BS9: =SOFR3mo_PX[[#This Row],[Column71]] -> 1205082 | BT9: =SOFR3mo_PX[[#This Row],[Column72]] -> 1202474 | BU9: =SOFR3mo_PX[[#This Row],[Column73]] -> 1189336 | BV9: =SOFR3mo_PX[[#This Row],[Column74]] -> 1197020 | BW9: =SOFR3mo_PX[[#This Row],[Column75]] -> 1203467 | BX9: =SOFR3mo_PX[[#This Row],[Column76]] -> 1202778 | BY9: =SOFR3mo_PX[[#This Row],[Column77]] -> 1218390 | BZ9: =SOFR3mo_PX[[#This Row],[Column78]] -> 1212442 | CA9: =SOFR3mo_PX[[#This Row],[Column79]] -> 1214121 | CB9: =SOFR3mo_PX[[#This Row],[Column80]] -> 1238494 | CC9: =SOFR3mo_PX[[#This Row],[Column81]] -> 1236453 | CD9: =SOFR3mo_PX[[#This Row],[Column82]] -> 1207269 | CE9: =SOFR3mo_PX[[#This Row],[Column83]] -> 914008 | CF9: =SOFR3mo_PX[[#This Row],[Column84]] -> 881578 | CG9: =SOFR3mo_PX[[#This Row],[Column85]] -> 871376 | CH9: =SOFR3mo_PX[[#This Row],[Column86]] -> 878244 | CI9: =SOFR3mo_PX[[#This Row],[Column87]] -> 878687 | CJ9: =SOFR3mo_PX[[#This Row],[Column88]] -> 884028 | CK9: =SOFR3mo_PX[[#This Row],[Column89]] -> 874845 | CL9: =SOFR3mo_PX[[#This Row],[Column90]] -> 867787 | CM9: =SOFR3mo_PX[[#This Row],[Column91]] -> 850571
A10: ='cont list_0'!I13 -> M28 | B10: =SOFR3mo_PX[[#This Row],[Column2]] -> 608103 | C10: =SOFR3mo_PX[[#This Row],[Column3]] -> 608103 | D10: =SOFR3mo_PX[[#This Row],[Column4]] -> 601476 | E10: =SOFR3mo_PX[[#This Row],[Column5]] -> 595223 | F10: =SOFR3mo_PX[[#This Row],[Column6]] -> 591761 | G10: =SOFR3mo_PX[[#This Row],[Column7]] -> 584316 | H10: =SOFR3mo_PX[[#This Row],[Column8]] -> 589497 | I10: =SOFR3mo_PX[[#This Row],[Column9]] -> 576442 | J10: =SOFR3mo_PX[[#This Row],[Column10]] -> 568240 | K10: =SOFR3mo_PX[[#This Row],[Column11]] -> 566129 | L10: =SOFR3mo_PX[[#This Row],[Column12]] -> 570602 | M10: =SOFR3mo_PX[[#This Row],[Column13]] -> 587728 | N10: =SOFR3mo_PX[[#This Row],[Column14]] -> 587521 | O10: =SOFR3mo_PX[[#This Row],[Column15]] -> 578596 | P10: =SOFR3mo_PX[[#This Row],[Column16]] -> 585170 | Q10: =SOFR3mo_PX[[#This Row],[Column17]] -> 576130 | R10: =SOFR3mo_PX[[#This Row],[Column18]] -> 692769 | S10: =SOFR3mo_PX[[#This Row],[Column19]] -> 700167 | T10: =SOFR3mo_PX[[#This Row],[Column20]] -> 694859 | U10: =SOFR3mo_PX[[#This Row],[Column21]] -> 695208 | V10: =SOFR3mo_PX[[#This Row],[Column22]] -> 675492 | W10: =SOFR3mo_PX[[#This Row],[Column23]] -> 682973 | X10: =SOFR3mo_PX[[#This Row],[Column24]] -> 683921 | Y10: =SOFR3mo_PX[[#This Row],[Column25]] -> 683921 | Z10: =SOFR3mo_PX[[#This Row],[Column26]] -> 674983 | AA10: =SOFR3mo_PX[[#This Row],[Column27]] -> 673186 | AB10: =SOFR3mo_PX[[#This Row],[Column28]] -> 665782 | AC10: =SOFR3mo_PX[[#This Row],[Column29]] -> 665492 | AD10: =SOFR3mo_PX[[#This Row],[Column30]] -> 670899 | AE10: =SOFR3mo_PX[[#This Row],[Column31]] -> 675003 | AF10: =SOFR3mo_PX[[#This Row],[Column32]] -> 677442 | AG10: =SOFR3mo_PX[[#This Row],[Column33]] -> 693222 | AH10: =SOFR3mo_PX[[#This Row],[Column34]] -> 691852 | AI10: =SOFR3mo_PX[[#This Row],[Column35]] -> 698125 | AJ10: =SOFR3mo_PX[[#This Row],[Column36]] -> 696681 | AK10: =SOFR3mo_PX[[#This Row],[Column37]] -> 712178 | AL10: =SOFR3mo_PX[[#This Row],[Column38]] -> 722375 | AM10: =SOFR3mo_PX[[#This Row],[Column39]] -> 720225 | AN10: =SOFR3mo_PX[[#This Row],[Column40]] -> 727098 | AO10: =SOFR3mo_PX[[#This Row],[Column41]] -> 725781 | AP10: =SOFR3mo_PX[[#This Row],[Column42]] -> 716107 | AQ10: =SOFR3mo_PX[[#This Row],[Column43]] -> 733317 | AR10: =SOFR3mo_PX[[#This Row],[Column44]] -> 735033 | AS10: =SOFR3mo_PX[[#This Row],[Column45]] -> 732701 | AT10: =SOFR3mo_PX[[#This Row],[Column46]] -> 737720 | AU10: =SOFR3mo_PX[[#This Row],[Column47]] -> 742400 | AV10: =SOFR3mo_PX[[#This Row],[Column48]] -> 745626 | AW10: =SOFR3mo_PX[[#This Row],[Column49]] -> 729674 | AX10: =SOFR3mo_PX[[#This Row],[Column50]] -> 722379 | AY10: =SOFR3mo_PX[[#This Row],[Column51]] -> 713163 | AZ10: =SOFR3mo_PX[[#This Row],[Column52]] -> 701659 | BA10: =SOFR3mo_PX[[#This Row],[Column53]] -> 694888 | BB10: =SOFR3mo_PX[[#This Row],[Column54]] -> 699563 | BC10: =SOFR3mo_PX[[#This Row],[Column55]] -> 703817 | BD10: =SOFR3mo_PX[[#This Row],[Column56]] -> 716453 | BE10: =SOFR3mo_PX[[#This Row],[Column57]] -> 714049 | BF10: =SOFR3mo_PX[[#This Row],[Column58]] -> 721344 | BG10: =SOFR3mo_PX[[#This Row],[Column59]] -> 720727 | BH10: =SOFR3mo_PX[[#This Row],[Column60]] -> 726888 | BI10: =SOFR3mo_PX[[#This Row],[Column61]] -> 735721 | BJ10: =SOFR3mo_PX[[#This Row],[Column62]] -> 730539 | BK10: =SOFR3mo_PX[[#This Row],[Column63]] -> 727400 | BL10: =SOFR3mo_PX[[#This Row],[Column64]] -> 726462 | BM10: =SOFR3mo_PX[[#This Row],[Column65]] -> 731443 | BN10: =SOFR3mo_PX[[#This Row],[Column66]] -> 727692 | BO10: =SOFR3mo_PX[[#This Row],[Column67]] -> 730001 | BP10: =SOFR3mo_PX[[#This Row],[Column68]] -> 738184 | BQ10: =SOFR3mo_PX[[#This Row],[Column69]] -> 733052 | BR10: =SOFR3mo_PX[[#This Row],[Column70]] -> 717210 | BS10: =SOFR3mo_PX[[#This Row],[Column71]] -> 717324 | BT10: =SOFR3mo_PX[[#This Row],[Column72]] -> 716716 | BU10: =SOFR3mo_PX[[#This Row],[Column73]] -> 718031 | BV10: =SOFR3mo_PX[[#This Row],[Column74]] -> 710613 | BW10: =SOFR3mo_PX[[#This Row],[Column75]] -> 700349 | BX10: =SOFR3mo_PX[[#This Row],[Column76]] -> 701531 | BY10: =SOFR3mo_PX[[#This Row],[Column77]] -> 701383 | BZ10: =SOFR3mo_PX[[#This Row],[Column78]] -> 708291 | CA10: =SOFR3mo_PX[[#This Row],[Column79]] -> 708189 | CB10: =SOFR3mo_PX[[#This Row],[Column80]] -> 698899 | CC10: =SOFR3mo_PX[[#This Row],[Column81]] -> 706544 | CD10: =SOFR3mo_PX[[#This Row],[Column82]] -> 714550 | CE10: =SOFR3mo_PX[[#This Row],[Column83]] -> 1196661 | CF10: =SOFR3mo_PX[[#This Row],[Column84]] -> 1189775 | CG10: =SOFR3mo_PX[[#This Row],[Column85]] -> 1185200 | CH10: =SOFR3mo_PX[[#This Row],[Column86]] -> 1162426 | CI10: =SOFR3mo_PX[[#This Row],[Column87]] -> 1165640 | CJ10: =SOFR3mo_PX[[#This Row],[Column88]] -> 1155345 | CK10: =SOFR3mo_PX[[#This Row],[Column89]] -> 1143265 | CL10: =SOFR3mo_PX[[#This Row],[Column90]] -> 1142701 | CM10: =SOFR3mo_PX[[#This Row],[Column91]] -> 1107316
A11: ='cont list_0'!I14 -> U28 | B11: =SOFR3mo_PX[[#This Row],[Column2]] -> 639838 | C11: =SOFR3mo_PX[[#This Row],[Column3]] -> 639838 | D11: =SOFR3mo_PX[[#This Row],[Column4]] -> 631849 | E11: =SOFR3mo_PX[[#This Row],[Column5]] -> 622970 | F11: =SOFR3mo_PX[[#This Row],[Column6]] -> 611201 | G11: =SOFR3mo_PX[[#This Row],[Column7]] -> 615528 | H11: =SOFR3mo_PX[[#This Row],[Column8]] -> 612625 | I11: =SOFR3mo_PX[[#This Row],[Column9]] -> 604702 | J11: =SOFR3mo_PX[[#This Row],[Column10]] -> 596550 | K11: =SOFR3mo_PX[[#This Row],[Column11]] -> 588590 | L11: =SOFR3mo_PX[[#This Row],[Column12]] -> 606455 | M11: =SOFR3mo_PX[[#This Row],[Column13]] -> 601130 | N11: =SOFR3mo_PX[[#This Row],[Column14]] -> 584142 | O11: =SOFR3mo_PX[[#This Row],[Column15]] -> 580834 | P11: =SOFR3mo_PX[[#This Row],[Column16]] -> 583461 | Q11: =SOFR3mo_PX[[#This Row],[Column17]] -> 576916 | R11: =SOFR3mo_PX[[#This Row],[Column18]] -> 566901 | S11: =SOFR3mo_PX[[#This Row],[Column19]] -> 588245 | T11: =SOFR3mo_PX[[#This Row],[Column20]] -> 577583 | U11: =SOFR3mo_PX[[#This Row],[Column21]] -> 579439 | V11: =SOFR3mo_PX[[#This Row],[Column22]] -> 584144 | W11: =SOFR3mo_PX[[#This Row],[Column23]] -> 604730 | X11: =SOFR3mo_PX[[#This Row],[Column24]] -> 607996 | Y11: =SOFR3mo_PX[[#This Row],[Column25]] -> 607996 | Z11: =SOFR3mo_PX[[#This Row],[Column26]] -> 617463 | AA11: =SOFR3mo_PX[[#This Row],[Column27]] -> 615150 | AB11: =SOFR3mo_PX[[#This Row],[Column28]] -> 611137 | AC11: =SOFR3mo_PX[[#This Row],[Column29]] -> 616403 | AD11: =SOFR3mo_PX[[#This Row],[Column30]] -> 624526 | AE11: =SOFR3mo_PX[[#This Row],[Column31]] -> 637566 | AF11: =SOFR3mo_PX[[#This Row],[Column32]] -> 662094 | AG11: =SOFR3mo_PX[[#This Row],[Column33]] -> 663989 | AH11: =SOFR3mo_PX[[#This Row],[Column34]] -> 680590 | AI11: =SOFR3mo_PX[[#This Row],[Column35]] -> 705698 | AJ11: =SOFR3mo_PX[[#This Row],[Column36]] -> 714330 | AK11: =SOFR3mo_PX[[#This Row],[Column37]] -> 714112 | AL11: =SOFR3mo_PX[[#This Row],[Column38]] -> 728078 | AM11: =SOFR3mo_PX[[#This Row],[Column39]] -> 720849 | AN11: =SOFR3mo_PX[[#This Row],[Column40]] -> 722343 | AO11: =SOFR3mo_PX[[#This Row],[Column41]] -> 722150 | AP11: =SOFR3mo_PX[[#This Row],[Column42]] -> 713586 | AQ11: =SOFR3mo_PX[[#This Row],[Column43]] -> 706200 | AR11: =SOFR3mo_PX[[#This Row],[Column44]] -> 704751 | AS11: =SOFR3mo_PX[[#This Row],[Column45]] -> 701307 | AT11: =SOFR3mo_PX[[#This Row],[Column46]] -> 663049 | AU11: =SOFR3mo_PX[[#This Row],[Column47]] -> 662070 | AV11: =SOFR3mo_PX[[#This Row],[Column48]] -> 656681 | AW11: =SOFR3mo_PX[[#This Row],[Column49]] -> 649042 | AX11: =SOFR3mo_PX[[#This Row],[Column50]] -> 648201 | AY11: =SOFR3mo_PX[[#This Row],[Column51]] -> 647874 | AZ11: =SOFR3mo_PX[[#This Row],[Column52]] -> 650493 | BA11: =SOFR3mo_PX[[#This Row],[Column53]] -> 656640 | BB11: =SOFR3mo_PX[[#This Row],[Column54]] -> 659953 | BC11: =SOFR3mo_PX[[#This Row],[Column55]] -> 654370 | BD11: =SOFR3mo_PX[[#This Row],[Column56]] -> 662611 | BE11: =SOFR3mo_PX[[#This Row],[Column57]] -> 662305 | BF11: =SOFR3mo_PX[[#This Row],[Column58]] -> 658478 | BG11: =SOFR3mo_PX[[#This Row],[Column59]] -> 654446 | BH11: =SOFR3mo_PX[[#This Row],[Column60]] -> 654593 | BI11: =SOFR3mo_PX[[#This Row],[Column61]] -> 654491 | BJ11: =SOFR3mo_PX[[#This Row],[Column62]] -> 655844 | BK11: =SOFR3mo_PX[[#This Row],[Column63]] -> 650134 | BL11: =SOFR3mo_PX[[#This Row],[Column64]] -> 645745 | BM11: =SOFR3mo_PX[[#This Row],[Column65]] -> 644857 | BN11: =SOFR3mo_PX[[#This Row],[Column66]] -> 642555 | BO11: =SOFR3mo_PX[[#This Row],[Column67]] -> 634530 | BP11: =SOFR3mo_PX[[#This Row],[Column68]] -> 638973 | BQ11: =SOFR3mo_PX[[#This Row],[Column69]] -> 632547 | BR11: =SOFR3mo_PX[[#This Row],[Column70]] -> 644553 | BS11: =SOFR3mo_PX[[#This Row],[Column71]] -> 632133 | BT11: =SOFR3mo_PX[[#This Row],[Column72]] -> 618267 | BU11: =SOFR3mo_PX[[#This Row],[Column73]] -> 621036 | BV11: =SOFR3mo_PX[[#This Row],[Column74]] -> 626602 | BW11: =SOFR3mo_PX[[#This Row],[Column75]] -> 617994 | BX11: =SOFR3mo_PX[[#This Row],[Column76]] -> 619303 | BY11: =SOFR3mo_PX[[#This Row],[Column77]] -> 602772 | BZ11: =SOFR3mo_PX[[#This Row],[Column78]] -> 609247 | CA11: =SOFR3mo_PX[[#This Row],[Column79]] -> 593861 | CB11: =SOFR3mo_PX[[#This Row],[Column80]] -> 588560 | CC11: =SOFR3mo_PX[[#This Row],[Column81]] -> 578483 | CD11: =SOFR3mo_PX[[#This Row],[Column82]] -> 583314 | CE11: =SOFR3mo_PX[[#This Row],[Column83]] -> 698709 | CF11: =SOFR3mo_PX[[#This Row],[Column84]] -> 687105 | CG11: =SOFR3mo_PX[[#This Row],[Column85]] -> 682022 | CH11: =SOFR3mo_PX[[#This Row],[Column86]] -> 686381 | CI11: =SOFR3mo_PX[[#This Row],[Column87]] -> 720423 | CJ11: =SOFR3mo_PX[[#This Row],[Column88]] -> 722609 | CK11: =SOFR3mo_PX[[#This Row],[Column89]] -> 702937 | CL11: =SOFR3mo_PX[[#This Row],[Column90]] -> 696587 | CM11: =SOFR3mo_PX[[#This Row],[Column91]] -> 708989
A12: ='cont list_0'!I15 -> Z28 | B12: =SOFR3mo_PX[[#This Row],[Column2]] -> 504467 | C12: =SOFR3mo_PX[[#This Row],[Column3]] -> 504467 | D12: =SOFR3mo_PX[[#This Row],[Column4]] -> 505038 | E12: =SOFR3mo_PX[[#This Row],[Column5]] -> 503819 | F12: =SOFR3mo_PX[[#This Row],[Column6]] -> 486641 | G12: =SOFR3mo_PX[[#This Row],[Column7]] -> 478680 | H12: =SOFR3mo_PX[[#This Row],[Column8]] -> 469903 | I12: =SOFR3mo_PX[[#This Row],[Column9]] -> 467190 | J12: =SOFR3mo_PX[[#This Row],[Column10]] -> 469372 | K12: =SOFR3mo_PX[[#This Row],[Column11]] -> 471006 | L12: =SOFR3mo_PX[[#This Row],[Column12]] -> 490898 | M12: =SOFR3mo_PX[[#This Row],[Column13]] -> 502253 | N12: =SOFR3mo_PX[[#This Row],[Column14]] -> 512906 | O12: =SOFR3mo_PX[[#This Row],[Column15]] -> 512569 | P12: =SOFR3mo_PX[[#This Row],[Column16]] -> 512035 | Q12: =SOFR3mo_PX[[#This Row],[Column17]] -> 505866 | R12: =SOFR3mo_PX[[#This Row],[Column18]] -> 573077 | S12: =SOFR3mo_PX[[#This Row],[Column19]] -> 568358 | T12: =SOFR3mo_PX[[#This Row],[Column20]] -> 566584 | U12: =SOFR3mo_PX[[#This Row],[Column21]] -> 550309 | V12: =SOFR3mo_PX[[#This Row],[Column22]] -> 509534 | W12: =SOFR3mo_PX[[#This Row],[Column23]] -> 506361 | X12: =SOFR3mo_PX[[#This Row],[Column24]] -> 497209 | Y12: =SOFR3mo_PX[[#This Row],[Column25]] -> 498156 | Z12: =SOFR3mo_PX[[#This Row],[Column26]] -> 491895 | AA12: =SOFR3mo_PX[[#This Row],[Column27]] -> 493402 | AB12: =SOFR3mo_PX[[#This Row],[Column28]] -> 493094 | AC12: =SOFR3mo_PX[[#This Row],[Column29]] -> 493778 | AD12: =SOFR3mo_PX[[#This Row],[Column30]] -> 484558 | AE12: =SOFR3mo_PX[[#This Row],[Column31]] -> 492224 | AF12: =SOFR3mo_PX[[#This Row],[Column32]] -> 491601 | AG12: =SOFR3mo_PX[[#This Row],[Column33]] -> 503553 | AH12: =SOFR3mo_PX[[#This Row],[Column34]] -> 507955 | AI12: =SOFR3mo_PX[[#This Row],[Column35]] -> 514645 | AJ12: =SOFR3mo_PX[[#This Row],[Column36]] -> 521927 | AK12: =SOFR3mo_PX[[#This Row],[Column37]] -> 525621 | AL12: =SOFR3mo_PX[[#This Row],[Column38]] -> 525634 | AM12: =SOFR3mo_PX[[#This Row],[Column39]] -> 512209 | AN12: =SOFR3mo_PX[[#This Row],[Column40]] -> 515976 | AO12: =SOFR3mo_PX[[#This Row],[Column41]] -> 509328 | AP12: =SOFR3mo_PX[[#This Row],[Column42]] -> 505380 | AQ12: =SOFR3mo_PX[[#This Row],[Column43]] -> 507701 | AR12: =SOFR3mo_PX[[#This Row],[Column44]] -> 511472 | AS12: =SOFR3mo_PX[[#This Row],[Column45]] -> 505305 | AT12: =SOFR3mo_PX[[#This Row],[Column46]] -> 501954 | AU12: =SOFR3mo_PX[[#This Row],[Column47]] -> 497579 | AV12: =SOFR3mo_PX[[#This Row],[Column48]] -> 499847 | AW12: =SOFR3mo_PX[[#This Row],[Column49]] -> 499378 | AX12: =SOFR3mo_PX[[#This Row],[Column50]] -> 499404 | AY12: =SOFR3mo_PX[[#This Row],[Column51]] -> 493970 | AZ12: =SOFR3mo_PX[[#This Row],[Column52]] -> 495745 | BA12: =SOFR3mo_PX[[#This Row],[Column53]] -> 501748 | BB12: =SOFR3mo_PX[[#This Row],[Column54]] -> 495271 | BC12: =SOFR3mo_PX[[#This Row],[Column55]] -> 496746 | BD12: =SOFR3mo_PX[[#This Row],[Column56]] -> 502522 | BE12: =SOFR3mo_PX[[#This Row],[Column57]] -> 494586 | BF12: =SOFR3mo_PX[[#This Row],[Column58]] -> 495065 | BG12: =SOFR3mo_PX[[#This Row],[Column59]] -> 494277 | BH12: =SOFR3mo_PX[[#This Row],[Column60]] -> 498537 | BI12: =SOFR3mo_PX[[#This Row],[Column61]] -> 496599 | BJ12: =SOFR3mo_PX[[#This Row],[Column62]] -> 491411 | BK12: =SOFR3mo_PX[[#This Row],[Column63]] -> 489819 | BL12: =SOFR3mo_PX[[#This Row],[Column64]] -> 487356 | BM12: =SOFR3mo_PX[[#This Row],[Column65]] -> 484557 | BN12: =SOFR3mo_PX[[#This Row],[Column66]] -> 484619 | BO12: =SOFR3mo_PX[[#This Row],[Column67]] -> 461061 | BP12: =SOFR3mo_PX[[#This Row],[Column68]] -> 458408 | BQ12: =SOFR3mo_PX[[#This Row],[Column69]] -> 455419 | BR12: =SOFR3mo_PX[[#This Row],[Column70]] -> 450354 | BS12: =SOFR3mo_PX[[#This Row],[Column71]] -> 453062 | BT12: =SOFR3mo_PX[[#This Row],[Column72]] -> 449041 | BU12: =SOFR3mo_PX[[#This Row],[Column73]] -> 446544 | BV12: =SOFR3mo_PX[[#This Row],[Column74]] -> 446463 | BW12: =SOFR3mo_PX[[#This Row],[Column75]] -> 444427 | BX12: =SOFR3mo_PX[[#This Row],[Column76]] -> 438439 | BY12: =SOFR3mo_PX[[#This Row],[Column77]] -> 448327 | BZ12: =SOFR3mo_PX[[#This Row],[Column78]] -> 455747 | CA12: =SOFR3mo_PX[[#This Row],[Column79]] -> 451475 | CB12: =SOFR3mo_PX[[#This Row],[Column80]] -> 457751 | CC12: =SOFR3mo_PX[[#This Row],[Column81]] -> 456977 | CD12: =SOFR3mo_PX[[#This Row],[Column82]] -> 458182 | CE12: =SOFR3mo_PX[[#This Row],[Column83]] -> 577271 | CF12: =SOFR3mo_PX[[#This Row],[Column84]] -> 577551 | CG12: =SOFR3mo_PX[[#This Row],[Column85]] -> 566476 | CH12: =SOFR3mo_PX[[#This Row],[Column86]] -> 585573 | CI12: =SOFR3mo_PX[[#This Row],[Column87]] -> 581026 | CJ12: =SOFR3mo_PX[[#This Row],[Column88]] -> 574290 | CK12: =SOFR3mo_PX[[#This Row],[Column89]] -> 551424 | CL12: =SOFR3mo_PX[[#This Row],[Column90]] -> 538374 | CM12: =SOFR3mo_PX[[#This Row],[Column91]] -> 541725
A13: ='cont list_0'!I16 -> H29 | B13: =SOFR3mo_PX[[#This Row],[Column2]] -> 368080 | C13: =SOFR3mo_PX[[#This Row],[Column3]] -> 368080 | D13: =SOFR3mo_PX[[#This Row],[Column4]] -> 367568 | E13: =SOFR3mo_PX[[#This Row],[Column5]] -> 370889 | F13: =SOFR3mo_PX[[#This Row],[Column6]] -> 364736 | G13: =SOFR3mo_PX[[#This Row],[Column7]] -> 364001 | H13: =SOFR3mo_PX[[#This Row],[Column8]] -> 362355 | I13: =SOFR3mo_PX[[#This Row],[Column9]] -> 360829 | J13: =SOFR3mo_PX[[#This Row],[Column10]] -> 364446 | K13: =SOFR3mo_PX[[#This Row],[Column11]] -> 365538 | L13: =SOFR3mo_PX[[#This Row],[Column12]] -> 364807 | M13: =SOFR3mo_PX[[#This Row],[Column13]] -> 368703 | N13: =SOFR3mo_PX[[#This Row],[Column14]] -> 382080 | O13: =SOFR3mo_PX[[#This Row],[Column15]] -> 386091 | P13: =SOFR3mo_PX[[#This Row],[Column16]] -> 381131 | Q13: =SOFR3mo_PX[[#This Row],[Column17]] -> 380181 | R13: =SOFR3mo_PX[[#This Row],[Column18]] -> 481528 | S13: =SOFR3mo_PX[[#This Row],[Column19]] -> 470342 | T13: =SOFR3mo_PX[[#This Row],[Column20]] -> 473390 | U13: =SOFR3mo_PX[[#This Row],[Column21]] -> 469965 | V13: =SOFR3mo_PX[[#This Row],[Column22]] -> 463810 | W13: =SOFR3mo_PX[[#This Row],[Column23]] -> 462540 | X13: =SOFR3mo_PX[[#This Row],[Column24]] -> 462309 | Y13: =SOFR3mo_PX[[#This Row],[Column25]] -> 462309 | Z13: =SOFR3mo_PX[[#This Row],[Column26]] -> 462860 | AA13: =SOFR3mo_PX[[#This Row],[Column27]] -> 460072 | AB13: =SOFR3mo_PX[[#This Row],[Column28]] -> 457872 | AC13: =SOFR3mo_PX[[#This Row],[Column29]] -> 457151 | AD13: =SOFR3mo_PX[[#This Row],[Column30]] -> 440396 | AE13: =SOFR3mo_PX[[#This Row],[Column31]] -> 451737 | AF13: =SOFR3mo_PX[[#This Row],[Column32]] -> 452818 | AG13: =SOFR3mo_PX[[#This Row],[Column33]] -> 444692 | AH13: =SOFR3mo_PX[[#This Row],[Column34]] -> 454934 | AI13: =SOFR3mo_PX[[#This Row],[Column35]] -> 453703 | AJ13: =SOFR3mo_PX[[#This Row],[Column36]] -> 446375 | AK13: =SOFR3mo_PX[[#This Row],[Column37]] -> 443222 | AL13: =SOFR3mo_PX[[#This Row],[Column38]] -> 447863 | AM13: =SOFR3mo_PX[[#This Row],[Column39]] -> 433442 | AN13: =SOFR3mo_PX[[#This Row],[Column40]] -> 425943 | AO13: =SOFR3mo_PX[[#This Row],[Column41]] -> 419461 | AP13: =SOFR3mo_PX[[#This Row],[Column42]] -> 420901 | AQ13: =SOFR3mo_PX[[#This Row],[Column43]] -> 422813 | AR13: =SOFR3mo_PX[[#This Row],[Column44]] -> 427106 | AS13: =SOFR3mo_PX[[#This Row],[Column45]] -> 429324 | AT13: =SOFR3mo_PX[[#This Row],[Column46]] -> 418127 | AU13: =SOFR3mo_PX[[#This Row],[Column47]] -> 415661 | AV13: =SOFR3mo_PX[[#This Row],[Column48]] -> 410434 | AW13: =SOFR3mo_PX[[#This Row],[Column49]] -> 400134 | AX13: =SOFR3mo_PX[[#This Row],[Column50]] -> 398097 | AY13: =SOFR3mo_PX[[#This Row],[Column51]] -> 391605 | AZ13: =SOFR3mo_PX[[#This Row],[Column52]] -> 403104 | BA13: =SOFR3mo_PX[[#This Row],[Column53]] -> 403214 | BB13: =SOFR3mo_PX[[#This Row],[Column54]] -> 404575 | BC13: =SOFR3mo_PX[[#This Row],[Column55]] -> 402051 | BD13: =SOFR3mo_PX[[#This Row],[Column56]] -> 400941 | BE13: =SOFR3mo_PX[[#This Row],[Column57]] -> 396818 | BF13: =SOFR3mo_PX[[#This Row],[Column58]] -> 397114 | BG13: =SOFR3mo_PX[[#This Row],[Column59]] -> 390883 | BH13: =SOFR3mo_PX[[#This Row],[Column60]] -> 389806 | BI13: =SOFR3mo_PX[[#This Row],[Column61]] -> 387905 | BJ13: =SOFR3mo_PX[[#This Row],[Column62]] -> 395073 | BK13: =SOFR3mo_PX[[#This Row],[Column63]] -> 393925 | BL13: =SOFR3mo_PX[[#This Row],[Column64]] -> 389793 | BM13: =SOFR3mo_PX[[#This Row],[Column65]] -> 390420 | BN13: =SOFR3mo_PX[[#This Row],[Column66]] -> 385847 | BO13: =SOFR3mo_PX[[#This Row],[Column67]] -> 379978 | BP13: =SOFR3mo_PX[[#This Row],[Column68]] -> 386370 | BQ13: =SOFR3mo_PX[[#This Row],[Column69]] -> 385214 | BR13: =SOFR3mo_PX[[#This Row],[Column70]] -> 380948 | BS13: =SOFR3mo_PX[[#This Row],[Column71]] -> 380948 | BT13: =SOFR3mo_PX[[#This Row],[Column72]] -> 371582 | BU13: =SOFR3mo_PX[[#This Row],[Column73]] -> 371285 | BV13: =SOFR3mo_PX[[#This Row],[Column74]] -> 376029 | BW13: =SOFR3mo_PX[[#This Row],[Column75]] -> 375372 | BX13: =SOFR3mo_PX[[#This Row],[Column76]] -> 371534 | BY13: =SOFR3mo_PX[[#This Row],[Column77]] -> 373079 | BZ13: =SOFR3mo_PX[[#This Row],[Column78]] -> 380498 | CA13: =SOFR3mo_PX[[#This Row],[Column79]] -> 374656 | CB13: =SOFR3mo_PX[[#This Row],[Column80]] -> 372854 | CC13: =SOFR3mo_PX[[#This Row],[Column81]] -> 370926 | CD13: =SOFR3mo_PX[[#This Row],[Column82]] -> 374736 | CE13: =SOFR3mo_PX[[#This Row],[Column83]] -> 460847 | CF13: =SOFR3mo_PX[[#This Row],[Column84]] -> 456636 | CG13: =SOFR3mo_PX[[#This Row],[Column85]] -> 455093 | CH13: =SOFR3mo_PX[[#This Row],[Column86]] -> 453889 | CI13: =SOFR3mo_PX[[#This Row],[Column87]] -> 458227 | CJ13: =SOFR3mo_PX[[#This Row],[Column88]] -> 455521 | CK13: =SOFR3mo_PX[[#This Row],[Column89]] -> 455526 | CL13: =SOFR3mo_PX[[#This Row],[Column90]] -> 458299 | CM13: =SOFR3mo_PX[[#This Row],[Column91]] -> 457431
